Workbook

Sheet Summary
A1: TATA ALTROZ — FRONT BUMPER ASSEMBLY · SHOULD-COST SUMMARY (INDIA)
A2: CostVision AI Cost Intelligence · July 2026 · Currency: INR, ex-works · Bottom-up physics build-up with live formulas
A4: # | B4: Cost block | C4: Basis | D4: ₹ / vehicle set | E4: % of total
A5: 1 | B5: Manufactured parts (18 line items) | C5: Bottom-up: material + process + labour + tooling amort + OH + margin | D5: ='Parts Costing'!$Z$22 | E5: =D5/$D$8
A6: 2 | B6: Bought-out parts & hardware | C6: Market reference + handling | D6: ='Bought-Out'!$G$11 | E6: =D6/$D$8
A7: 3 | B7: Assembly & packing | C7: Station labour + fixtures + overhead + dunnage | D7: ='Assembly & Packing'!$F$17 | E7: =D7/$D$8
B8: TOTAL SHOULD COST — FRONT BUMPER ASSEMBLY | D8: =SUM(D5:D7) | E8: 1
B10: Mechanical module only (excl. electronics: sensors, radar, camera, harness) | D10: =D8-'Bought-Out'!$G$12
B11: One-time tooling & equipment investment (amortised in the prices above) | D11: =Tooling!B7
B12: Annual volume assumption | D12: =Assumptions!$B$4
B13: Painted fascia only (compare against fascia-only quotes) | D13: ='Parts Costing'!Y4+'Parts Costing'!Y5
A15: COST BREAKDOWN — THREE VIEWS (1: mechanical vs electronics · 2: cost structure · 3: part-level)
A34: TOP COST DRIVERS
A35: 1. Front radar sensor (bought-out) | D35: ='Bought-Out'!G5 | E35: Largest single item — negotiate LTA with annual step-downs
A36: 2. Painted fascia (moulding + paint) | D36: ='Parts Costing'!Z4+'Parts Costing'!Z5 | E36: Largest manufactured item — see savings idea #1
A37: 3. Front camera module (bought-out) | D37: ='Bought-Out'!G6 | E37: Directed part — bundle with radar for leverage
A38: 4. Parking sensors ×4 (bought-out) | D38: ='Bought-Out'!G4 | E38: Sensor count is trim-dependent (Assumptions B44)
A39: 5. Reinforcement beam (form + weld) | D39: ='Parts Costing'!Z12+'Parts Costing'!Z13 | E39: Steel mass dominates — gauge optimisation is the lever
A41: KEY NOTES & BASIS
A42: 1. Basis: ex-works tier-1 supplier, India, 2026 rates. Edit any yellow cell (Assumptions / Parts Costing) — every figure recalculates.
A43: 2. Masses & cycle times are engineering estimates from typical B-segment bumper benchmarks — replace with actual CAD/part weights when available.
A44: 3. Electronics (radar, camera, sensors, harness) are customer-nominated buy items shown at market reference prices, not bottom-up should-costs.
A45: 4. Drawing notes PP for grilles while the part list says ABS — costed as PP (textured black, typical for this segment); switch material price ref on Parts Costing if ABS.
A46: 5. Parking sensor count set to 4 (base trim). Part list allows 4–8 — change one cell on Assumptions (B44) for higher trims.
A47: 6. Tooling amortised over volume × 5 years into piece price. For tooling paid separately by OEM, set tool costs to 0 on Parts Costing (column S).
A48: 7. Paint: fascia costed body-colour painted (material + robotic line). Delete row 5 on Parts Costing if supplied moulded-in-colour.
A49: 8. Logistics to OEM plant, warranty and ED/GST excluded (per should-cost convention).
A50: 9. COMPARING TO A QUOTE: match the scope first. A bumper supplier quote normally EXCLUDES radar/camera/sensors/harness (directed parts) and often the steel beam — compare it to the mechanical-module or painted-fascia lines above, not the headline total.
A52: COST-SAVING IDEAS (VA/VE) — indicative ₹/vehicle, each needs engineering validation
A53: # | B53: Idea | C53: Area | D53: Saving ₹/veh
A54: 1 | B54: Moulded-in-colour fascia — delete the paint operation entirely | C54: Fascia | D54: ='Parts Costing'!Y5
A55: 2 | B55: TPO resin long-term agreement / price indexing (−₹10/kg) | C55: Material | D55: ='Parts Costing'!F4*(1+'Parts Costing'!G4)*10
A56: 3 | B56: Closed-loop runner regrind reuse instead of selling scrap | C56: Material | D56: 8
A57: 4 | B57: Conformal-cooled fascia mould — cycle −6 s | C57: Process | D57: =6*Assumptions!$B$21/3600*1.6
A58: 5 | B58: Beam gauge/grade optimisation — take 0.4 kg out of the steel | C58: Beam | D58: =0.4*Assumptions!$B$15*1.3
A59: 6 | B59: Integrate bracket piercing into rollform — fewer weld operations | C59: Beam | D59: 12
A60: 7 | B60: EPP density 45 → 38 g/l (validated crash performance) | C60: Energy absorber | D60: =0.04*Assumptions!$B$13*1.35
A61: 8 | B61: Mould sensor-holder bosses into fascia — delete 4 parts + 1 tool | C61: Small parts | D61: ='Parts Costing'!Z16
A62: 9 | B62: Family mould: wheel-arch retainers + side supports in one tool | C62: Tooling | D62: 6
A63: 10 | B63: Snap-fits replace 6 screws (fascia dress parts) | C63: Fasteners / assembly | D63: 18
...

Sheet Methodology & Q&A
A1: How this should-cost was calculated — step by step
A2: Read top to bottom. The right-hand column shows LIVE numbers pulled by formula from the costing sheets (worked example: front bumper fascia).
A3: THE 8-STEP METHOD (worked example on the right: Front Bumper Fascia — values are LIVE, they change if you edit inputs)
A4: 1 | B4: Break the assembly into parts and decide make vs buy | C4: The 26-line part list from the drawing was split into: 18 MANUFACTURED items (we cost these bottom-up on the Parts Costing sheet) and 7 BOUGHT-OUT items (electronics & standard hardware — no one should-costs a radar chip bottom-up; we use market reference prices + 3% handling on the Bought-Out sheet). | D4: Manufactured line items
A5: 2 | B5: Material cost per part | C5: Net part mass × (1 + scrap%) × material price ₹/kg, minus scrap credit for the recoverable portion. Formula in words: you buy slightly more plastic/steel than ends up in the part (runners, offal), and sell back what you can. Excel: =Mass×(1+Scrap)×Price − Mass×Scrap×Credit → Fascia: 3.60 kg TPO at ₹155/kg with 4% runner scrap. | D5: Fascia material ₹
D6: ='Parts Costing'!J4
A7: 3 | B7: Process (machine) cost | C7: Cycle time ÷ 3600 × machine hour rate ÷ cavities. The machine rate (Assumptions sheet) is a full build-up: depreciation + energy @ ₹8.5/kWh + maintenance + floor space + supervision. A 1500-tonne press at ₹2,100/hr running a 55 s cycle costs ₹32.08 of machine time per shot — big-ticket machines, small per-part cost, because the hour is shared across every part made in it. | D7: Fascia process ₹
D8: ='Parts Costing'!O4
A9: 4 | B9: Direct labour | C9: Cycle time × manning × labour rate ÷ 3600 ÷ cavities. Manning below 1.0 means one operator tends several machines (standard moulding practice — 0.5 = one operator per two presses). Labour rates are FULLY LOADED: wages + statutory contributions + benefits + supervision share. | D9: Fascia labour ₹
D10: ='Parts Costing'!R4
A11: 5 | B11: Tooling amortisation | C11: Tool cost ÷ (annual volume × amortisation years × parts per vehicle). The ₹1.8 Cr fascia mould spread over 72,000 vehicles × 5 years = a per-part charge (₹50/part). This is the number most sensitive to VOLUME — halve the volume and this line doubles. If the OEM pays for tooling separately, set column S to zero on Parts Costing. | D11: Fascia tooling ₹/pc
D12: ='Parts Costing'!T4
A13: 6 | B13: Overheads and margin | C13: Factory overhead (40%) is applied on CONVERSION cost only (process + labour), never on material — a supplier does not "manage" resin price, so it earns no overhead on it. Then SG&A 8% on manufacturing cost, and 10% profit on top of that. The result is the ex-works unit price we should expect a competitive tier-1 to quote. | D13: Fascia unit price ₹
D14: ='Parts Costing'!Y4
A15: 7 | B15: Assembly & packing | C15: Six stations, each = manned seconds × operators × labour rate. Add fixture and end-of-line equipment amortisation, 45% assembly overhead on the labour, consumables, and the returnable-dunnage trip cost. Bumper assembly is clip-and-screw work — it is deliberately cheap (~1% of total). | D15: Assembly & packing ₹
D16: ='Assembly & Packing'!$F$17
A17: 8 | B17: Roll up the total | C17: Total = Σ(manufactured unit price × qty) + Σ(bought-out landed × qty) + assembly & packing. The Summary sheet also shows the MECHANICAL-ONLY subtotal (excluding radar/camera/sensors/harness) because that is the number to compare against a bumper supplier's quote — the electronics are usually priced separately. | D17: TOTAL should cost ₹
D18: =Summary!D8
A20: DEEP-DIVE: PAINT COST — how the body-colour paint line item is built (all values LIVE)
A21: P1 | B21: Paint material — ₹160/bumper | C21: Primer + basecoat + clearcoat + thinners, materials only. Basis: ~0.40 litre of mixed paint per bumper at OEM robotic transfer efficiency, ~₹400/litre blended across the three coats. This is an input (Assumptions B18) — put in our paint shop's actual chemical cost per unit if we have it. | D21: Paint material ₹
D22: =Assumptions!$B$18
A23: P2 | B23: Paint line time — the biggest piece | C23: A conveyorised robotic bumper paint line costs ₹2,400/hr all-in: booth depreciation, ventilation and booth energy (the big consumers), robots, sludge/filter handling. At ~110 s effective takt per bumper: 110 ÷ 3600 × 2,400. Painting is a PROCESS cost — the booth hour, not the paint, is what you pay for. | D23: Line cost ₹/bumper
D24: ='Parts Costing'!O5
A25: P3 | B25: Labour — small by design | C25: Robotic line: 0.5 manning (loader/unloader shared) × skilled rate ₹260/hr × 110 s. Manual painting would triple this and hurt quality consistency. | D25: Paint labour ₹
D26: ='Parts Costing'!R5
A27: P4 | B27: Paint jigs & masks — ₹60 L amortised | C27: Bumper-specific carriers, masking jigs and skids, spread over volume × years like any tool: ₹60 L ÷ 360,000 bumpers. | D27: Jig amortisation ₹
D28: ='Parts Costing'!T5
A29: P5 | B29: Overhead + markups | C29: Factory overhead 40% on the conversion (line + labour, NOT on paint material), then SG&A 8% and profit 10% like every other line. | D29: Paint line item ₹
D30: ='Parts Costing'!Y5
A31: P6 | B31: Sanity checks & the lever | C31: Checks: India tier-1 bumper paint jobs benchmark at ₹280–₹380 all-in — we sit mid-range. First-run yield ~92–95% is assumed inside the line rate. The lever: if the fascia can be moulded-in-colour (masterbatch), this entire line item disappears — savings idea #1.
A33: DEEP-DIVE: TOOLING — what is in the investment and how it reaches the piece price (all values LIVE)
A34: T1 | B34: What the investment covers | C34: Injection moulds for every plastic part, the EPP shape mould, rollform tooling for the beam, the progressive die for crash-box brackets, weld fixtures, paint jigs, assembly fixtures and end-of-line equipment. Parts tooling ₹6.28 Cr + assembly fixtures ₹0.40 Cr + EOL equipment ₹0.60 Cr. | D34: Total investment ₹
D35: =Tooling!B7
A36: T2 | B36: The biggest tool — fascia mould ₹1.8 Cr | C36: A single-cavity hot-runner mould for a 1500-tonne press, ~3.6 kg part with texture and complex shut-offs. India toolroom benchmark: ₹1.5–2.5 Cr (the same tool imported from Japan/Korea would be 2–3×). Next: paint jigs ₹60 L, grille moulds ₹50 L each, beam rollform set ₹50 L, EPP mould ₹35 L. | D36: Fascia mould ₹
D37: ='Parts Costing'!S4
A38: T3 | B38: The amortisation formula | C38: Tool ÷ (annual volume × years × parts per vehicle). Fascia: ₹1.8 Cr ÷ (72,000 × 5 × 1) = ₹50.00 per part. Every tool row uses the same formula — column T on Parts Costing. | D38: Fascia amort ₹/pc
D39: ='Parts Costing'!T4
A40: T4 | B40: Family tools cost less per piece | C40: LH+RH parts share one mould and come out in the same shot, so the tool spreads over twice the pieces: side brackets ₹18 L ÷ (72,000 × 5 × 2) = ₹2.50/pc. The sensor holder runs 4 cavities for the same reason. | D40: Side-bracket amort ₹/pc
D41: ='Parts Costing'!T8
A42: T5 | B42: Tool life check — why 5 years is safe | C42: 5 years × 72,000 = 360,000 shots on the fascia mould. A hardened hot-runner bumper mould is good for 500k–1M shots, so life does not limit the amortisation period; small tools are specified hardened (H13/P20) for the same duty.
...

Sheet Assumptions
A1: CostVision — Should-Cost Assumptions & Rate Card (India, 2026)
A2: Every figure below is an input — edit any cell and the whole workbook recalculates. Sources: India tier-1 benchmarks, July 2026.
A3: PROGRAMME
A4: Annual vehicle volume | B4: 72000 | C4: veh/yr | D4: Altroz-class volume assumption — EDIT to your programme volume; all amortisation recalculates.
A5: Tooling amortisation period | B5: 5 | C5: years | D5: Tooling amortised into piece price over volume × years (standard should-cost practice).
A6: Currency | B6: INR | D6: All values in Indian Rupees, ex-works supplier (logistics to OEM excluded).
A7: FX reference | B7: 106 | C7: INR/GBP | D7: Reference only — no conversion applied in this workbook.
A9: MATERIAL PRICES (₹/kg, delivered India plant)
A10: PP (black, textured grade) | B10: 112 | C10: ₹/kg | D10: PP copolymer ₹110–120/kg India spot (OfBusiness, Jul 2026); OEM contract mid-range.
A11: PP+EPDM (TPO bumper grade) | B11: 155 | C11: ₹/kg | D11: PP copolymer + EPDM/talc compounding premium ~₹35–45/kg; paintable bumper grade.
A12: ABS (plating/paint grade) | B12: 158 | C12: ₹/kg | D12: ABS coloured/auto grade ₹155–170/kg India (OfBusiness, Jul 2026).
A13: EPP beads (45 g/l) | B13: 700 | C13: ₹/kg | D13: Delivered India automotive grade (imported beads + duty + freight); FOB China ~₹330 — corrected per procurement input.
A14: POM (clips) | B14: 210 | C14: ₹/kg | D14: Reference for clip costing (bought-out set used instead).
A15: High-strength steel sheet (HR, 590+) | B15: 68 | C15: ₹/kg | D15: For reinforcement beam & steel brackets.
A16: Steel scrap credit | B16: 32 | C16: ₹/kg | D16: Offal / engineered scrap sold back.
A17: Plastic regrind credit | B17: 40 | C17: ₹/kg | D17: Runner/sprue regrind value (where not reused).
A18: Paint material per bumper (primer+base+clear) | B18: 160 | C18: ₹/unit | D18: Body-colour robotic paint, material only.
A20: MACHINE RATES (₹/hr — includes depreciation, energy @ ₹8.5/kWh, maintenance, floor space, supervision)
A21: Injection moulding 1500T | B21: 2100 | C21: ₹/hr | D21: For bumper fascia.
A22: Injection moulding 800T | B22: 1150 | C22: ₹/hr | D22: Spare class (unused by default).
A23: Injection moulding 450T | B23: 700 | C23: ₹/hr | D23: Grilles, air deflector.
A24: Injection moulding 250T | B24: 520 | C24: ₹/hr | D24: Bezels, wheel-arch retainers.
A25: Injection moulding 150T | B25: 400 | C25: ₹/hr | D25: Small brackets, holders, covers.
A26: EPP shape-moulding machine | B26: 650 | C26: ₹/hr | D26: Steam-chest moulding for energy absorber.
A27: Progressive press 250T (with feeder) | B27: 900 | C27: ₹/hr | D27: Steel beam brackets.
A28: Rollform + pierce + sweep line | B28: 1600 | C28: ₹/hr | D28: Reinforcement beam forming.
A29: MIG/spot weld cell | B29: 800 | C29: ₹/hr | D29: Beam bracket welding.
A30: Robotic paint line (bumper) | B30: 2400 | C30: ₹/hr | D30: Conveyorised, incl. booth energy & ventilation.
A32: LABOUR RATES (₹/hr, fully loaded — wages + statutory + benefits + supervision share)
A33: Operator (semi-skilled) | B33: 190 | C33: ₹/hr | D33: Press/moulding/assembly operator.
A34: Skilled (setter / welder / painter) | B34: 260 | C34: ₹/hr
A35: Quality inspector | B35: 230 | C35: ₹/hr | D35: End-of-line checks.
A37: COMMERCIAL FACTORS
A38: Factory overhead (on conversion cost) | B38: 0.4 | C38: % | D38: Indirect staff, utilities, quality system, maintenance overheads.
A39: SG&A | B39: 0.08 | C39: % | D39: Sales, general & administrative on manufacturing cost.
A40: Profit | B40: 0.1 | C40: % | D40: Supplier margin on manufacturing cost + SG&A.
A41: Bought-out handling & inbound | B41: 0.03 | C41: % | D41: Applied to bought-out (pass-through) items.
A42: Assembly overhead (on assembly conversion) | B42: 0.45 | C42: % | D42: Line management, MHE, utilities at assembly plant.
A43: Packaging per finished assembly | B43: 55 | C43: ₹/unit | D43: Returnable dunnage trip cost, amortised.
A44: Parking sensors fitted | B44: 4 | C44: pcs | D44: Part list says 4–8 — set 4 (base) to 8 (top trim); sensors, holders & BOM recalc.

Sheet Parts Costing
A1: Parts Costing — bottom-up build-up per manufactured part
A2: Yellow cells are inputs (masses/cycles are engineering estimates — replace with actuals when available). All ₹ columns are live formulas.
A3: Sr | B3: Part / Operation | C3: Process | D3: Material | E3: Qty/veh | F3: Net mass (kg) | G3: Scrap % | H3: Mat. price (₹/kg) | I3: Scrap credit (₹/kg) | J3: Material ₹ | K3: Machine / Line | L3: Machine rate (₹/hr) | M3: Cycle (s) | N3: Cav. | O3: Process ₹ | P3: Manning | Q3: Labour rate (₹/hr) | R3: Labour ₹ | S3: Tool cost ₹ (total) | T3: Tool amort ₹/pc | U3: Overhead ₹ | V3: Mfg cost ₹ | W3: SG&A ₹ | X3: Profit ₹ | Y3: Unit price ₹ | Z3: Extended ₹/veh | AA3: Photo
A4: 1 | B4: Front bumper fascia | C4: Injection moulding | D4: PP+EPDM (TPO) | E4: 1 | F4: 3.6 | G4: 0.04 | H4: =Assumptions!$B$11 | I4: =Assumptions!$B$17 | J4: =F4*(1+G4)*H4-F4*G4*I4 | K4: IMM 1500T | L4: =Assumptions!$B$21 | M4: 55 | N4: 1 | O4: =M4*L4/3600/N4 | P4: 0.5 | Q4: =Assumptions!$B$33 | R4: =M4*P4*Q4/3600/N4 | S4: 18000000 | T4: =S4/(Assumptions!$B$4*Assumptions!$B$5*E4) | U4: =(O4+R4)*Assumptions!$B$38 | V4: =J4+O4+R4+T4+U4 | W4: =V4*Assumptions!$B$39 | X4: =(V4+W4)*Assumptions!$B$40 | Y4: =V4+W4+X4 | Z4: =Y4*E4
A5: 2 | B5: Painting — fascia, body colour | C5: Robotic paint (P+B+C) | D5: Paint system | E5: 1 | J5: =Assumptions!$B$18 | K5: Paint line | L5: =Assumptions!$B$30 | M5: 110 | N5: 1 | O5: =M5*L5/3600/N5 | P5: 0.5 | Q5: =Assumptions!$B$34 | R5: =M5*P5*Q5/3600/N5 | S5: 6000000 | T5: =S5/(Assumptions!$B$4*Assumptions!$B$5*E5) | U5: =(O5+R5)*Assumptions!$B$38 | V5: =J5+O5+R5+T5+U5 | W5: =V5*Assumptions!$B$39 | X5: =(V5+W5)*Assumptions!$B$40 | Y5: =V5+W5+X5 | Z5: =Y5*E5
A6: 3 | B6: Upper grille | C6: Injection moulding | D6: PP (textured) | E6: 1 | F6: 0.45 | G6: 0.05 | H6: =Assumptions!$B$10 | I6: =Assumptions!$B$17 | J6: =F6*(1+G6)*H6-F6*G6*I6 | K6: IMM 450T | L6: =Assumptions!$B$23 | M6: 32 | N6: 1 | O6: =M6*L6/3600/N6 | P6: 0.33 | Q6: =Assumptions!$B$33 | R6: =M6*P6*Q6/3600/N6 | S6: 5000000 | T6: =S6/(Assumptions!$B$4*Assumptions!$B$5*E6) | U6: =(O6+R6)*Assumptions!$B$38 | V6: =J6+O6+R6+T6+U6 | W6: =V6*Assumptions!$B$39 | X6: =(V6+W6)*Assumptions!$B$40 | Y6: =V6+W6+X6 | Z6: =Y6*E6
A7: 4 | B7: Lower grille | C7: Injection moulding | D7: PP (textured) | E7: 1 | F7: 0.55 | G7: 0.05 | H7: =Assumptions!$B$10 | I7: =Assumptions!$B$17 | J7: =F7*(1+G7)*H7-F7*G7*I7 | K7: IMM 450T | L7: =Assumptions!$B$23 | M7: 38 | N7: 1 | O7: =M7*L7/3600/N7 | P7: 0.33 | Q7: =Assumptions!$B$33 | R7: =M7*P7*Q7/3600/N7 | S7: 5000000 | T7: =S7/(Assumptions!$B$4*Assumptions!$B$5*E7) | U7: =(O7+R7)*Assumptions!$B$38 | V7: =J7+O7+R7+T7+U7 | W7: =V7*Assumptions!$B$39 | X7: =(V7+W7)*Assumptions!$B$40 | Y7: =V7+W7+X7 | Z7: =Y7*E7
A8: 5 | B8: Side bracket LH+RH (fascia) | C8: Injection moulding | D8: PP | E8: 2 | F8: 0.12 | G8: 0.04 | H8: =Assumptions!$B$10 | I8: =Assumptions!$B$17 | J8: =F8*(1+G8)*H8-F8*G8*I8 | K8: IMM 150T | L8: =Assumptions!$B$25 | M8: 26 | N8: 2 | O8: =M8*L8/3600/N8 | P8: 0.25 | Q8: =Assumptions!$B$33 | R8: =M8*P8*Q8/3600/N8 | S8: 1800000 | T8: =S8/(Assumptions!$B$4*Assumptions!$B$5*E8) | U8: =(O8+R8)*Assumptions!$B$38 | V8: =J8+O8+R8+T8+U8 | W8: =V8*Assumptions!$B$39 | X8: =(V8+W8)*Assumptions!$B$40 | Y8: =V8+W8+X8 | Z8: =Y8*E8
A9: 6 | B9: Number / licence plate bracket | C9: Injection moulding | D9: PP | E9: 1 | F9: 0.18 | G9: 0.04 | H9: =Assumptions!$B$10 | I9: =Assumptions!$B$17 | J9: =F9*(1+G9)*H9-F9*G9*I9 | K9: IMM 150T | L9: =Assumptions!$B$25 | M9: 28 | N9: 1 | O9: =M9*L9/3600/N9 | P9: 0.25 | Q9: =Assumptions!$B$33 | R9: =M9*P9*Q9/3600/N9 | S9: 1200000 | T9: =S9/(Assumptions!$B$4*Assumptions!$B$5*E9) | U9: =(O9+R9)*Assumptions!$B$38 | V9: =J9+O9+R9+T9+U9 | W9: =V9*Assumptions!$B$39 | X9: =(V9+W9)*Assumptions!$B$40 | Y9: =V9+W9+X9 | Z9: =Y9*E9
A10: 7 | B10: Fog lamp bezel / DRL housing LH+RH | C10: Injection moulding | D10: ABS | E10: 2 | F10: 0.15 | G10: 0.05 | H10: =Assumptions!$B$12 | I10: =Assumptions!$B$17 | J10: =F10*(1+G10)*H10-F10*G10*I10 | K10: IMM 250T | L10: =Assumptions!$B$24 | M10: 34 | N10: 2 | O10: =M10*L10/3600/N10 | P10: 0.33 | Q10: =Assumptions!$B$33 | R10: =M10*P10*Q10/3600/N10 | S10: 2800000 | T10: =S10/(Assumptions!$B$4*Assumptions!$B$5*E10) | U10: =(O10+R10)*Assumptions!$B$38 | V10: =J10+O10+R10+T10+U10 | W10: =V10*Assumptions!$B$39 | X10: =(V10+W10)*Assumptions!$B$40 | Y10: =V10+W10+X10 | Z10: =Y10*E10
A11: 8 | B11: Energy absorber | C11: EPP shape moulding | D11: EPP foam 45 g/l | E11: 1 | F11: 0.25 | G11: 0.02 | H11: =Assumptions!$B$13 | I11: =Assumptions!$B$17 | J11: =F11*(1+G11)*H11-F11*G11*I11 | K11: EPP moulder | L11: =Assumptions!$B$26 | M11: 90 | N11: 1 | O11: =M11*L11/3600/N11 | P11: 0.5 | Q11: =Assumptions!$B$33 | R11: =M11*P11*Q11/3600/N11 | S11: 3500000 | T11: =S11/(Assumptions!$B$4*Assumptions!$B$5*E11) | U11: =(O11+R11)*Assumptions!$B$38 | V11: =J11+O11+R11+T11+U11 | W11: =V11*Assumptions!$B$39 | X11: =(V11+W11)*Assumptions!$B$40 | Y11: =V11+W11+X11 | Z11: =Y11*E11
A12: 9 | B12: Reinforcement beam — form & pierce | C12: Rollform + sweep | D12: HSS 590 sheet | E12: 1 | F12: 4.2 | G12: 0.08 | H12: =Assumptions!$B$15 | I12: =Assumptions!$B$16 | J12: =F12*(1+G12)*H12-F12*G12*I12 | K12: Rollform line | L12: =Assumptions!$B$28 | M12: 45 | N12: 1 | O12: =M12*L12/3600/N12 | P12: 1 | Q12: =Assumptions!$B$33 | R12: =M12*P12*Q12/3600/N12 | S12: 5000000 | T12: =S12/(Assumptions!$B$4*Assumptions!$B$5*E12) | U12: =(O12+R12)*Assumptions!$B$38 | V12: =J12+O12+R12+T12+U12 | W12: =V12*Assumptions!$B$39 | X12: =(V12+W12)*Assumptions!$B$40 | Y12: =V12+W12+X12 | Z12: =Y12*E12
A13: 10 | B13: Reinforcement beam — bracket welding | C13: MIG weld op | D13: (consumables in rate) | E13: 1 | J13: 0 | K13: Weld cell | L13: =Assumptions!$B$29 | M13: 60 | N13: 1 | O13: =M13*L13/3600/N13 | P13: 1 | Q13: =Assumptions!$B$34 | R13: =M13*P13*Q13/3600/N13 | S13: 1500000 | T13: =S13/(Assumptions!$B$4*Assumptions!$B$5*E13) | U13: =(O13+R13)*Assumptions!$B$38 | V13: =J13+O13+R13+T13+U13 | W13: =V13*Assumptions!$B$39 | X13: =(V13+W13)*Assumptions!$B$40 | Y13: =V13+W13+X13 | Z13: =Y13*E13
A14: 11 | B14: Side beam bracket LH+RH (crash-box) | C14: Progressive stamping | D14: HSS 590 sheet | E14: 2 | F14: 0.35 | G14: 0.12 | H14: =Assumptions!$B$15 | I14: =Assumptions!$B$16 | J14: =F14*(1+G14)*H14-F14*G14*I14 | K14: Press 250T prog | L14: =Assumptions!$B$27 | M14: 12 | N14: 2 | O14: =M14*L14/3600/N14 | P14: 0.5 | Q14: =Assumptions!$B$33 | R14: =M14*P14*Q14/3600/N14 | S14: 2500000 | T14: =S14/(Assumptions!$B$4*Assumptions!$B$5*E14) | U14: =(O14+R14)*Assumptions!$B$38 | V14: =J14+O14+R14+T14+U14 | W14: =V14*Assumptions!$B$39 | X14: =(V14+W14)*Assumptions!$B$40 | Y14: =V14+W14+X14 | Z14: =Y14*E14
A15: 12 | B15: Tow hook cover | C15: Injection moulding | D15: PP | E15: 1 | F15: 0.05 | G15: 0.04 | H15: =Assumptions!$B$10 | I15: =Assumptions!$B$17 | J15: =F15*(1+G15)*H15-F15*G15*I15 | K15: IMM 150T | L15: =Assumptions!$B$25 | M15: 22 | N15: 2 | O15: =M15*L15/3600/N15 | P15: 0.25 | Q15: =Assumptions!$B$33 | R15: =M15*P15*Q15/3600/N15 | S15: 900000 | T15: =S15/(Assumptions!$B$4*Assumptions!$B$5*E15) | U15: =(O15+R15)*Assumptions!$B$38 | V15: =J15+O15+R15+T15+U15 | W15: =V15*Assumptions!$B$39 | X15: =(V15+W15)*Assumptions!$B$40 | Y15: =V15+W15+X15 | Z15: =Y15*E15
A16: 13 | B16: Parking sensor holder | C16: Injection moulding | D16: PP | E16: =Assumptions!$B$44 | F16: 0.02 | G16: 0.04 | H16: =Assumptions!$B$10 | I16: =Assumptions!$B$17 | J16: =F16*(1+G16)*H16-F16*G16*I16 | K16: IMM 150T | L16: =Assumptions!$B$25 | M16: 20 | N16: 4 | O16: =M16*L16/3600/N16 | P16: 0.25 | Q16: =Assumptions!$B$33 | R16: =M16*P16*Q16/3600/N16 | S16: 1400000 | T16: =S16/(Assumptions!$B$4*Assumptions!$B$5*E16) | U16: =(O16+R16)*Assumptions!$B$38 | V16: =J16+O16+R16+T16+U16 | W16: =V16*Assumptions!$B$39 | X16: =(V16+W16)*Assumptions!$B$40 | Y16: =V16+W16+X16 | Z16: =Y16*E16
A17: 14 | B17: Radar sensor bracket | C17: Injection moulding | D17: PP | E17: 1 | F17: 0.08 | G17: 0.04 | H17: =Assumptions!$B$10 | I17: =Assumptions!$B$17 | J17: =F17*(1+G17)*H17-F17*G17*I17 | K17: IMM 150T | L17: =Assumptions!$B$25 | M17: 25 | N17: 2 | O17: =M17*L17/3600/N17 | P17: 0.25 | Q17: =Assumptions!$B$33 | R17: =M17*P17*Q17/3600/N17 | S17: 1100000 | T17: =S17/(Assumptions!$B$4*Assumptions!$B$5*E17) | U17: =(O17+R17)*Assumptions!$B$38 | V17: =J17+O17+R17+T17+U17 | W17: =V17*Assumptions!$B$39 | X17: =(V17+W17)*Assumptions!$B$40 | Y17: =V17+W17+X17 | Z17: =Y17*E17
A18: 15 | B18: Camera mount bracket | C18: Injection moulding | D18: PP | E18: 1 | F18: 0.05 | G18: 0.04 | H18: =Assumptions!$B$10 | I18: =Assumptions!$B$17 | J18: =F18*(1+G18)*H18-F18*G18*I18 | K18: IMM 150T | L18: =Assumptions!$B$25 | M18: 22 | N18: 2 | O18: =M18*L18/3600/N18 | P18: 0.25 | Q18: =Assumptions!$B$33 | R18: =M18*P18*Q18/3600/N18 | S18: 900000 | T18: =S18/(Assumptions!$B$4*Assumptions!$B$5*E18) | U18: =(O18+R18)*Assumptions!$B$38 | V18: =J18+O18+R18+T18+U18 | W18: =V18*Assumptions!$B$39 | X18: =(V18+W18)*Assumptions!$B$40 | Y18: =V18+W18+X18 | Z18: =Y18*E18
A19: 16 | B19: Air deflector | C19: Injection moulding | D19: PP | E19: 1 | F19: 0.35 | G19: 0.05 | H19: =Assumptions!$B$10 | I19: =Assumptions!$B$17 | J19: =F19*(1+G19)*H19-F19*G19*I19 | K19: IMM 450T | L19: =Assumptions!$B$23 | M19: 33 | N19: 1 | O19: =M19*L19/3600/N19 | P19: 0.33 | Q19: =Assumptions!$B$33 | R19: =M19*P19*Q19/3600/N19 | S19: 3000000 | T19: =S19/(Assumptions!$B$4*Assumptions!$B$5*E19) | U19: =(O19+R19)*Assumptions!$B$38 | V19: =J19+O19+R19+T19+U19 | W19: =V19*Assumptions!$B$39 | X19: =(V19+W19)*Assumptions!$B$40 | Y19: =V19+W19+X19 | Z19: =Y19*E19
A20: 17 | B20: Wheel-arch retainer LH+RH | C20: Injection moulding | D20: PP | E20: 2 | F20: 0.15 | G20: 0.04 | H20: =Assumptions!$B$10 | I20: =Assumptions!$B$17 | J20: =F20*(1+G20)*H20-F20*G20*I20 | K20: IMM 250T | L20: =Assumptions!$B$24 | M20: 30 | N20: 2 | O20: =M20*L20/3600/N20 | P20: 0.33 | Q20: =Assumptions!$B$33 | R20: =M20*P20*Q20/3600/N20 | S20: 1600000 | T20: =S20/(Assumptions!$B$4*Assumptions!$B$5*E20) | U20: =(O20+R20)*Assumptions!$B$38 | V20: =J20+O20+R20+T20+U20 | W20: =V20*Assumptions!$B$39 | X20: =(V20+W20)*Assumptions!$B$40 | Y20: =V20+W20+X20 | Z20: =Y20*E20
A21: 18 | B21: Side support bracket LH+RH | C21: Injection moulding | D21: PP | E21: 2 | F21: 0.15 | G21: 0.04 | H21: =Assumptions!$B$10 | I21: =Assumptions!$B$17 | J21: =F21*(1+G21)*H21-F21*G21*I21 | K21: IMM 250T | L21: =Assumptions!$B$24 | M21: 30 | N21: 2 | O21: =M21*L21/3600/N21 | P21: 0.33 | Q21: =Assumptions!$B$33 | R21: =M21*P21*Q21/3600/N21 | S21: 1600000 | T21: =S21/(Assumptions!$B$4*Assumptions!$B$5*E21) | U21: =(O21+R21)*Assumptions!$B$38 | V21: =J21+O21+R21+T21+U21 | W21: =V21*Assumptions!$B$39 | X21: =(V21+W21)*Assumptions!$B$40 | Y21: =V21+W21+X21 | Z21: =Y21*E21
B22: MANUFACTURED PARTS — TOTAL PER VEHICLE | S22: =SUM(S4:S21) | Z22: =SUM(Z4:Z21)

Sheet Bought-Out
A1: Bought-Out / Directed Parts — market reference prices (India OEM volumes)
A2: Electronics are typically customer-nominated buy items — prices are market references for completeness, not bottom-up should-costs.
A3: Sr | B3: Item | C3: Category | D3: Qty/veh | E3: Unit price ₹ | F3: Handling ₹ | G3: Landed ₹/veh
A4: 1 | B4: Ultrasonic parking sensor | C4: Electronics | D4: =Assumptions!$B$44 | E4: 220 | F4: =E4*Assumptions!$B$41 | G4: =(E4+F4)*D4
A5: 2 | B5: Front radar sensor (77 GHz) | C5: Electronics | D5: 1 | E5: 3200 | F5: =E5*Assumptions!$B$41 | G5: =(E5+F5)*D5
A6: 3 | B6: Front camera module | C6: Electronics | D6: 1 | E6: 1500 | F6: =E6*Assumptions!$B$41 | G6: =(E6+F6)*D6
A7: 4 | B7: Bumper wiring harness | C7: Electrical | D7: 1 | E7: 420 | F7: =E7*Assumptions!$B$41 | G7: =(E7+F7)*D7
A8: 5 | B8: Clips & fasteners set (push clips, u-nuts, spring nuts) | C8: Hardware | D8: 1 | E8: 95 | F8: =E8*Assumptions!$B$41 | G8: =(E8+F8)*D8
A9: 6 | B9: Bolts M8/M10 set | C9: Hardware | D9: 1 | E9: 28 | F9: =E9*Assumptions!$B$41 | G9: =(E9+F9)*D9
A10: 7 | B10: Nuts & washers set | C10: Hardware | D10: 1 | E10: 20 | F10: =E10*Assumptions!$B$41 | G10: =(E10+F10)*D10
B11: BOUGHT-OUT — TOTAL PER VEHICLE | G11: =SUM(G4:G10)
B12: of which electronics (sensors + radar + camera + harness) | G12: =SUM(G4:G7)

Sheet Assembly & Packing
A1: Assembly & Packing — station-by-station conversion cost
A2: Manned time per station × fully-loaded labour rate + fixture/equipment amortisation + overhead + returnable packaging.
A3: St. | B3: Station / Operation | C3: Time (s) | D3: Operators | E3: Labour rate (₹/hr) | F3: Labour ₹/unit | G3: Notes
A4: 1 | B4: Beam sub-assembly: energy absorber + crash brackets to beam | C4: 60 | D4: 1 | E4: =Assumptions!$B$33 | F4: =C4*D4*E4/3600 | G4: Bolted, torque-monitored
A5: 2 | B5: Fascia dress: grilles, bezels, number-plate bracket, tow cover | C5: 120 | D5: 2 | E5: =Assumptions!$B$33 | F5: =C5*D5*E5/3600 | G5: Clip-fit + screw stations
A6: 3 | B6: Harness routing, parking sensors, radar & camera fit | C6: 150 | D6: 1.5 | E6: =Assumptions!$B$33 | F6: =C6*D6*E6/3600 | G6: Connector click-checks
A7: 4 | B7: Air deflector, wheel-arch retainers, side supports | C7: 75 | D7: 1 | E7: =Assumptions!$B$33 | F7: =C7*D7*E7/3600
A8: 5 | B8: End-of-line inspection & torque verification | C8: 60 | D8: 1 | E8: =Assumptions!$B$35 | F8: =C8*D8*E8/3600 | G8: Poka-yoke checklist
A9: 6 | B9: Pack into returnable dunnage | C9: 45 | D9: 1 | E9: =Assumptions!$B$33 | F9: =C9*D9*E9/3600
B11: Assembly labour subtotal | F11: =SUM(F4:F9)
B12: Fixtures & jigs amortisation (₹40 L over volume × years) | F12: =4000000/(Assumptions!$B$4*Assumptions!$B$5) | G12: Assembly fixtures, torque tools mounting
B13: Equipment amortisation (EOL tester, torque tools — ₹60 L) | F13: =6000000/(Assumptions!$B$4*Assumptions!$B$5)
B14: Consumables per unit | F14: 6 | G14: Tapes, primers, gloves
B15: Assembly overhead | F15: =F11*Assumptions!$B$42 | G15: On labour subtotal — rate from Assumptions
B16: Packaging (returnable dunnage trip cost) | F16: =Assumptions!$B$43
B17: ASSEMBLY & PACKING — TOTAL PER VEHICLE | F17: =SUM(F11:F16)

Sheet Tooling
A1: Tooling & Investment Summary
A2: One-time investment; amortised into piece price over volume × years (see Assumptions). Change any tool cost on Parts Costing.
A3: Item | B3: Value
A4: Part tooling total (moulds, dies, fixtures) | B4: ='Parts Costing'!S22
A5: Assembly fixtures & jigs | B5: 4000000
A6: Assembly equipment (EOL, torque) | B6: 6000000
A7: TOTAL ONE-TIME INVESTMENT | B7: =SUM(B4:B6)
A9: In ₹ Crore | B9: =B7/10000000
