Workbook

Sheet Start here
A1: CostVision rate card converter
A2: Put your own rates into CostVision without retyping them. Seven steps, about ten minutes the first time.
A4: WHAT THIS IS FOR
B5: You get a rate card in your own layout, with your own codes. CostVision needs its own ids,
B6: because those ids are what its costing formulas look for. This workbook joins the two.
B7: You paste your rates in. It fills in the file CostVision reads. Nothing is renamed, and
B8: there is no code to change. It is ordinary Excel formulas, so there are no macros to allow.
A10: BEFORE YOU START
B11: Have your machine rate card and your material rate card open.
B12: If labour comes as its own file, have that too. If it does not, you will not need one.
B13: Know the country you are costing in, and the period stamped on each file.
A15: THE SEVEN STEPS
A16: STEP 1 | B16: Paste the machine rates.
B17: a. Go to the tab called JLR Machines.
B18: b. Row 2 is an example. Click the row 2 number, right-click, and choose Delete Row.
B19: c. In your machine file, select all the rows of data. Not the header row.
B20: d. Come back here, click cell A2 , and paste. Use Paste Special → Values if you have it.
B21: e. Look across: MACHINE_CODE should be in column A, TOTAL_MACHINE_RATE in column N.
B22: Row 1 already has your 14 headers on it, in the shaded band. Leave that row alone.
B23: If your file has extra columns, or has them in a different order, tidy your copy first so
B24: the columns line up with row 1 here. Paste as many rows as you like, all countries
B25: included. Step 4 is what picks out the ones you want.
A27: STEP 2 | B27: Paste the material rates.
B28: Same again on the JLR Materials tab. Delete the example on row 2, then paste your
B29: rows into cell A2 . CODE goes in column A, CO2 in column G.
A31: STEP 3 | B31: Paste the labour rates, if you have them separately.
B32: On the card we have seen, labour is already inside the machine file, as
B33: TOTAL_LABOUR_RATE next to a LABOUR_CATEGORY. If that is true for you, skip this step.
B34: Go to JLR Labour , delete the example rows, and leave the tab empty. The sheet will
B35: find labour on the machine tab instead.
B36: If you do have a separate labour file, delete the examples and paste into A2 as before.
A38: STEP 4 | B38: Say which country and which period you want.
B39: Go to the Settings tab and fill in the four shaded cells in column B:
B40: B2 Country for example United Kingdom
B41: B3 Machine period for example 04042025 (copy it from PERIOD_CODE)
B42: B4 Material period for example 04-04-2025 (copy it from PERIOD)
B43: B5 MATERIAL_RECLAIM choose percent or per kg
B44: Type each one exactly as it appears in your file, spaces and dashes and all. Copying it
B45: straight out of the file is safer than typing it.
B46: There are two period boxes on purpose. The two files write the same quarter differently.
...

Sheet How it converts
A1: How it converts
A2: Every rule this workbook applies, in plain words, with the formula that does it. Nothing here is hidden in code.
A4: The short version
B5: Your rate card and CostVision hold the same numbers in different shapes.
B6: A machine rate on your card is seven costs per hour that add up to TOTAL_MACHINE_RATE.
B7: CostVision holds the same seven as yearly costs, and divides by hours x utilisation to get back to an hourly rate.
B8: So this sheet multiplies each of your hourly figures by that machine’s hours x utilisation. CostVision divides it straight back out.
B9: The rate lands on your published number, and the split survives, so a report can still show what the rate is made of.
B10: Materials and labour are simpler: the price and the hourly rate go straight across.
A12: The machine rate, line by line
A13: Each of your seven hourly figures becomes one yearly figure. 3,200 in the formula below is that machine’s own 4,000 hours x 80% utilisation — the same number CostVision divides by afterwards, so it cancels.
B14: From your file | C14: Becomes, in CostVision | D14: What happens to it | E14: The formula, as it is in the sheet
B15: DEPRECIATION | C15: annualDepreciation | D15: Depreciation x hours x utilisation, plus the penny the seven elements round by, so the rebuilt rate equals TOTAL_MACHINE_RATE exactly. | E15: IF($X2>0,IF($Y2>0,MAX(0,$Q2+$X2-$Y2)*3200,$X2*3200),40480)
B16: MRO | C16: maintenance | D16: MRO x hours x utilisation. | E16: IF($X2>0,IF($Y2>0,$S2*3200,0),22211)
B17: UTILITIES | C17: energy | D17: Utilities x hours x utilisation. | E17: IF($X2>0,IF($Y2>0,$V2*3200,0),23304)
B18: FLOORSPACE | C18: floorSpace | D18: Floorspace x hours x utilisation. | E18: IF($X2>0,IF($Y2>0,$R2*3200,0),8077)
B19: INSURANCE + CONSUMABLES | C19: indirectSupport | D19: Insurance and consumables together — CostVision has one line where the card has two. | E19: IF($X2>0,IF($Y2>0,($T2+$W2)*3200,0),22158)
B20: INTEREST | C20: financeCost | D20: Interest x hours x utilisation. | E20: IF($X2>0,IF($Y2>0,$U2*3200,0),16000)
B21: TOTAL_MACHINE_RATE | C21: nothing directly | D21: Used as the switch — if there is a rate for this machine, take your figures; if not, keep ours. Also used to check the answer. | E21: IF($X2<=0,0,ROUND((D2+E2+F2+G2+H2+I2)/3200-$X2,4))
B22: If a row has only a TOTAL_MACHINE_RATE and no breakdown, the whole total goes on the depreciation line and the source note says so, rather than pretending to be a breakdown.
A25: Materials
B26: From your file | C26: Becomes, in CostVision | D26: What happens to it | E26: The formula, as it is in the sheet
B27: MATERIAL_RATE | C27: pricePerKg | D27: Your price per kilo, or ours when you have not mapped this one. | E27: IF($M2>0,$M2,3.56)
B28: MATERIAL_RECLAIM | C28: scrapRecoveryPricePerKg | D28: The scrap credit, worked out in column O from whichever basis Settings says. | E28: IF($O2>0,$O2,0.54)
B29: MATERIAL_RECLAIM | C29: working: scrap £/kg | D29: Percent of the rate, or a price per kilo already. Settings B5 decides. | E29: IF($N2=0,0,IF(Settings!$B$5="percent",$M2*$N2/100,$N2))
B30: CO2 | C30: nothing | D30: Brought onto the Materials tab so you can see it. CostVision has no carbon field in this file, so it is ignored on upload. | E30: (no formula — the column is carried across only)
A33: Labour
B34: From your file | C34: Becomes, in CostVision | D34: What happens to it | E34: The formula, as it is in the sheet
B35: TOTAL_LABOUR_RATE | C35: fullyLoadedRatePerHr | D35: Your hourly rate for that labour category, or ours when it is not mapped. | E35: IF($L2>0,$L2,26.19)
B36: TOTAL_LABOUR_RATE on JLR Machines | C36: working: from the machine tab | D36: If there is no separate labour file, read the category off the machine rows instead. | E36: IF($H2="",0,IFERROR(AVERAGEIFS('JLR Machines'!$F$2:$F$20001,'JLR Machines'!$E$2:$E$20001,$H2,'JLR Machines'!$C$2:$C$20001,IF(Settings!$B$2="","<>",Settings!$B$2),'JLR Machines'!$D$2:$D$20001,IF(Settings!$B$3="","<>",Settings!$B$3)),0))
A39: The three rules underneath all of it
B40: From your file | C40: Becomes, in CostVision | D40: What happens to it | E40: The formula, as it is in the sheet
B41: Mapping column C | C41: which code to use | D41: Finds the code you typed on the Mapping tab for this row. Empty means "not mapped", and the row keeps our value. | E41: IFERROR(INDEX(Mapping!$C$2:$C$549,MATCH($A2,Mapping!$A$2:$A$549,0)),"")
B42: COUNTRY + PERIOD | C42: how many rows match | D42: Counts the pasted rows with this code, in the country and period you asked for on Settings. Only a count of exactly 1 is used. Two means the filter has not narrowed it, and a made-up average would be a rate nobody published. | E42: IF($K2="",0,COUNTIFS('JLR Materials'!$A$2:$A$20001,$K2,'JLR Materials'!$C$2:$C$20001,IF(Settings!$B$2="","<>",Settings!$B$2),'JLR Materials'!$D$2:$D$20001,IF(Settings!$B$4="","<>",Settings!$B$4)))
B43: the matched row | C43: the number itself | D43: Reads one column off that single matching row. Zero when there is no clean single match, which every formula above reads as "keep what CostVision already had". | E43: IF($L2<>1,0,SUMIFS('JLR Materials'!$E$2:$E$20001,'JLR Materials'!$A$2:$A$20001,$K2,'JLR Materials'!$C$2:$C$20001,IF(Settings!$B$2="","<>",Settings!$B$2),'JLR Materials'!$D$2:$D$20001,IF(Settings!$B$4="","<>",Settings!$B$4)))
A46: Where to find the working in the sheet
B47: From your file | C47: Becomes, in CostVision | D47: What happens to it | E47: The formula, as it is in the sheet
B48: Materials | C48: K to P are the working columns. Q and R hold our own note and date, for when yours is not used.
B49: Machines | C49: O to Z are the working columns. AA and AB hold our own note and date.
B50: Labour | C50: H to L are the working columns. M holds our own note.
...

Sheet Settings
A1: Setting | B1: Value | C1: What it does
A2: Country | C2: Type it exactly as your file writes it, e.g. United Kingdom. Leave empty to take any.
A3: Machine period | C3: The PERIOD_CODE on your machine and labour files, e.g. 04042025.
A4: Material period | C4: The PERIOD on your material file, e.g. 04-04-2025. The two files write it differently.
A5: MATERIAL_RECLAIM is | B5: percent | C5: Is it a percentage of the material rate, or already a price per kilo? Please check.
B8: The shaded boxes are the only things to fill in on this tab.
B9: Leave a box empty only if you have already cut that file down to one country and one period.
B10: If a code ends up matching two rows, the Check tab will tell you, and CostVision keeps its
B11: own value for that row rather than guessing which of the two you meant.

Sheet JLR Machines
A1: MACHINE_CODE | B1: MACHINE_NAME | C1: COUNTRY_NAME | D1: PERIOD_CODE | E1: LABOUR_CATEGORY | F1: TOTAL_LABOUR_RATE | G1: DEPRECIATION | H1: FLOORSPACE | I1: MRO | J1: INSURANCE | K1: INTEREST | L1: UTILITIES | M1: CONSUMABLES | N1: TOTAL_MACHINE_RATE
A2: EXAMPLE | B2: EXAMPLE ROW, DELETE IT — your machine export goes here, from cell A2 down | C2: United Kingdom | D2: 04042025 | E2: CB | F2: 40.97 | G2: 1.75 | H2: 1.06 | I2: 1.97 | J2: 0.18 | K2: 0.64 | L2: 4.45 | M2: 0 | N2: 10.06

Sheet JLR Materials
A1: CODE | B1: MATERIAL | C1: COUNTRY | D1: PERIOD | E1: MATERIAL_RATE | F1: MATERIAL_RECLAIM | G1: CO2
A2: EXAMPLE | B2: EXAMPLE ROW, DELETE IT — your material export goes here, from cell A2 down | C2: United Kingdom | D2: 04-04-2025 | E2: 0.72 | F2: 40.48 | G2: 2.19

Sheet JLR Labour
A1: LABOUR_CATEGORY | B1: DESCRIPTION | C1: COUNTRY_NAME | D1: PERIOD_CODE | E1: TOTAL_LABOUR_RATE
A2: EXAMPLE | B2: EXAMPLE ROW, DELETE IT — or leave this whole tab empty, and the sheet will read TOTAL_LABOUR_RATE off the JLR Machines tab by LABOUR_CATEGORY instead | C2: United Kingdom | D2: 04042025 | E2: 40.97

Sheet Mapping
A1: tool id | B1: what it is (do not edit) | C1: JLR code | D1: JLR name for that code | E1: category
A2: mat-al6061 | B2: 6061-T6 — Aluminium — UK | D2: =IF($C2="","",IFERROR(IF($E2="machine",INDEX('JLR Machines'!$B$2:$B$20001,MATCH($C2,'JLR Machines'!$A$2:$A$20001,0)),IF($E2="material",INDEX('JLR Materials'!$B$2:$B$20001,MATCH($C2,'JLR Materials'!$A$2:$A$20001,0)),IF($E2="labour",IFERROR(INDEX('JLR Labour'!$B$2:$B$20001,MATCH($C2,'JLR Labour'!$A$2:$A$20001,0)),"labour category "&$C2&" — from the machine tab"),""))),"NOT FOUND — check the code")) | E2: material
A3: mat-steel1045 | B3: 1045 / C45 / 080M46 (Medium-Carbon Steel) — Carbon Steel — UK | D3: =IF($C3="","",IFERROR(IF($E3="machine",INDEX('JLR Machines'!$B$2:$B$20001,MATCH($C3,'JLR Machines'!$A$2:$A$20001,0)),IF($E3="material",INDEX('JLR Materials'!$B$2:$B$20001,MATCH($C3,'JLR Materials'!$A$2:$A$20001,0)),IF($E3="labour",IFERROR(INDEX('JLR Labour'!$B$2:$B$20001,MATCH($C3,'JLR Labour'!$A$2:$A$20001,0)),"labour category "&$C3&" — from the machine tab"),""))),"NOT FOUND — check the code")) | E3: material
A4: mat-ss316l | B4: 316L — Stainless Steel — UK | D4: =IF($C4="","",IFERROR(IF($E4="machine",INDEX('JLR Machines'!$B$2:$B$20001,MATCH($C4,'JLR Machines'!$A$2:$A$20001,0)),IF($E4="material",INDEX('JLR Materials'!$B$2:$B$20001,MATCH($C4,'JLR Materials'!$A$2:$A$20001,0)),IF($E4="labour",IFERROR(INDEX('JLR Labour'!$B$2:$B$20001,MATCH($C4,'JLR Labour'!$A$2:$A$20001,0)),"labour category "&$C4&" — from the machine tab"),""))),"NOT FOUND — check the code")) | E4: material
A5: mat-steel4140 | B5: 4140 / 42CrMo4 / EN19 (Chromoly Alloy Steel) — Alloy Steel — UK | D5: =IF($C5="","",IFERROR(IF($E5="machine",INDEX('JLR Machines'!$B$2:$B$20001,MATCH($C5,'JLR Machines'!$A$2:$A$20001,0)),IF($E5="material",INDEX('JLR Materials'!$B$2:$B$20001,MATCH($C5,'JLR Materials'!$A$2:$A$20001,0)),IF($E5="labour",IFERROR(INDEX('JLR Labour'!$B$2:$B$20001,MATCH($C5,'JLR Labour'!$A$2:$A$20001,0)),"labour category "&$C5&" — from the machine tab"),""))),"NOT FOUND — check the code")) | E5: material
A6: mat-ti6al4v | B6: Ti-6Al-4V — Titanium — UK | D6: =IF($C6="","",IFERROR(IF($E6="machine",INDEX('JLR Machines'!$B$2:$B$20001,MATCH($C6,'JLR Machines'!$A$2:$A$20001,0)),IF($E6="material",INDEX('JLR Materials'!$B$2:$B$20001,MATCH($C6,'JLR Materials'!$A$2:$A$20001,0)),IF($E6="labour",IFERROR(INDEX('JLR Labour'!$B$2:$B$20001,MATCH($C6,'JLR Labour'!$A$2:$A$20001,0)),"labour category "&$C6&" — from the machine tab"),""))),"NOT FOUND — check the code")) | E6: material
A7: mat-virtual | B7: Virtual / Pass-through — Virtual — UK | D7: =IF($C7="","",IFERROR(IF($E7="machine",INDEX('JLR Machines'!$B$2:$B$20001,MATCH($C7,'JLR Machines'!$A$2:$A$20001,0)),IF($E7="material",INDEX('JLR Materials'!$B$2:$B$20001,MATCH($C7,'JLR Materials'!$A$2:$A$20001,0)),IF($E7="labour",IFERROR(INDEX('JLR Labour'!$B$2:$B$20001,MATCH($C7,'JLR Labour'!$A$2:$A$20001,0)),"labour category "&$C7&" — from the machine tab"),""))),"NOT FOUND — check the code")) | E7: material
A8: mat-en8 | B8: EN8 / 080M40 (Medium Carbon) — Carbon Steel — UK | D8: =IF($C8="","",IFERROR(IF($E8="machine",INDEX('JLR Machines'!$B$2:$B$20001,MATCH($C8,'JLR Machines'!$A$2:$A$20001,0)),IF($E8="material",INDEX('JLR Materials'!$B$2:$B$20001,MATCH($C8,'JLR Materials'!$A$2:$A$20001,0)),IF($E8="labour",IFERROR(INDEX('JLR Labour'!$B$2:$B$20001,MATCH($C8,'JLR Labour'!$A$2:$A$20001,0)),"labour category "&$C8&" — from the machine tab"),""))),"NOT FOUND — check the code")) | E8: material
A9: mat-ss304-bar | B9: 304 Stainless Bar — Stainless Steel — UK | D9: =IF($C9="","",IFERROR(IF($E9="machine",INDEX('JLR Machines'!$B$2:$B$20001,MATCH($C9,'JLR Machines'!$A$2:$A$20001,0)),IF($E9="material",INDEX('JLR Materials'!$B$2:$B$20001,MATCH($C9,'JLR Materials'!$A$2:$A$20001,0)),IF($E9="labour",IFERROR(INDEX('JLR Labour'!$B$2:$B$20001,MATCH($C9,'JLR Labour'!$A$2:$A$20001,0)),"labour category "&$C9&" — from the machine tab"),""))),"NOT FOUND — check the code")) | E9: material
A10: mat-ss303 | B10: 303 Free-Machining Stainless Bar — Stainless Steel — UK | D10: =IF($C10="","",IFERROR(IF($E10="machine",INDEX('JLR Machines'!$B$2:$B$20001,MATCH($C10,'JLR Machines'!$A$2:$A$20001,0)),IF($E10="material",INDEX('JLR Materials'!$B$2:$B$20001,MATCH($C10,'JLR Materials'!$A$2:$A$20001,0)),IF($E10="labour",IFERROR(INDEX('JLR Labour'!$B$2:$B$20001,MATCH($C10,'JLR Labour'!$A$2:$A$20001,0)),"labour category "&$C10&" — from the machine tab"),""))),"NOT FOUND — check the code")) | E10: material
A11: mat-al6082-bar | B11: 6082-T6 Aluminium Bar — Aluminium — UK | D11: =IF($C11="","",IFERROR(IF($E11="machine",INDEX('JLR Machines'!$B$2:$B$20001,MATCH($C11,'JLR Machines'!$A$2:$A$20001,0)),IF($E11="material",INDEX('JLR Materials'!$B$2:$B$20001,MATCH($C11,'JLR Materials'!$A$2:$A$20001,0)),IF($E11="labour",IFERROR(INDEX('JLR Labour'!$B$2:$B$20001,MATCH($C11,'JLR Labour'!$A$2:$A$20001,0)),"labour category "&$C11&" — from the machine tab"),""))),"NOT FOUND — check the code")) | E11: material
A12: mat-al2011 | B12: 2011-T3 Free-Machining Al Bar — Aluminium — UK | D12: =IF($C12="","",IFERROR(IF($E12="machine",INDEX('JLR Machines'!$B$2:$B$20001,MATCH($C12,'JLR Machines'!$A$2:$A$20001,0)),IF($E12="material",INDEX('JLR Materials'!$B$2:$B$20001,MATCH($C12,'JLR Materials'!$A$2:$A$20001,0)),IF($E12="labour",IFERROR(INDEX('JLR Labour'!$B$2:$B$20001,MATCH($C12,'JLR Labour'!$A$2:$A$20001,0)),"labour category "&$C12&" — from the machine tab"),""))),"NOT FOUND — check the code")) | E12: material
A13: mat-brass-cz121 | B13: CZ121 / CW614N Free-Machining Brass — Copper Alloy — UK | D13: =IF($C13="","",IFERROR(IF($E13="machine",INDEX('JLR Machines'!$B$2:$B$20001,MATCH($C13,'JLR Machines'!$A$2:$A$20001,0)),IF($E13="material",INDEX('JLR Materials'!$B$2:$B$20001,MATCH($C13,'JLR Materials'!$A$2:$A$20001,0)),IF($E13="labour",IFERROR(INDEX('JLR Labour'!$B$2:$B$20001,MATCH($C13,'JLR Labour'!$A$2:$A$20001,0)),"labour category "&$C13&" — from the machine tab"),""))),"NOT FOUND — check the code")) | E13: material
... A549: lab-ro-semiskilled | B549: Semi-skilled Operator — Romania | D549: =IF($C549="","",IFERROR(IF($E549="machine",INDEX('JLR Machines'!$B$2:$B$20001,MATCH($C549,'JLR Machines'!$A$2:$A$20001,0)),IF($E549="material",INDEX('JLR Materials'!$B$2:$B$20001,MATCH($C549,'JLR Materials'!$A$2:$A$20001,0)),IF($E549="labour",IFERROR(INDEX('JLR Labour'!$B$2:$B$20001,MATCH($C549,'JLR Labour'!$A$2:$A$20001,0)),"labour category "&$C549&" — from the machine tab"),""))),"NOT FOUND — check the code")) | E549: labour

Sheet Materials
A1: id | B1: grade | C1: category | D1: pricePerKg | E1: scrapRecoveryPricePerKg | F1: densityKgPerM3 | G1: region | H1: effectiveDate | I1: sourceNote | J1: confidence | K1: JLR code | L1: rows matched | M1: MATERIAL_RATE | N1: MATERIAL_RECLAIM | O1: scrap £/kg | P1: CO2 (not used) | Q1: built-in source note | R1: built-in date
A2: mat-al6061 | B2: 6061-T6 | C2: Aluminium | D2: =IF($M2>0,$M2,3.56) -> 3.56 | E2: =IF($O2>0,$O2,0.54) -> 0.54 | F2: 2700 | G2: UK | H2: =IF($M2>0,IF($L2<>1,$R2,IFERROR(INDEX('JLR Materials'!$D$2:$D$20001,MATCH($K2,'JLR Materials'!$A$2:$A$20001,0)),$R2)),$R2) -> 2026-09 | I2: =IF($M2>0,"JLR rate card — material code "&$K2,$Q2) -> LME + UK processor premium, Jun 2026. Index-anchored 2026-07 refresh. | Refresh 2026-09: −£0.060/kg from 0.97kg al £2.910→£2.849/kg; premiums held | J2: Medium | K2: =IFERROR(INDEX(Mapping!$C$2:$C$549,MATCH($A2,Mapping!$A$2:$A$549,0)),"") | L2: =IF($K2="",0,COUNTIFS('JLR Materials'!$A$2:$A$20001,$K2,'JLR Materials'!$C$2:$C$20001,IF(Settings!$B$2="","<>",Settings!$B$2),'JLR Materials'!$D$2:$D$20001,IF(Settings!$B$4="","<>",Settings!$B$4))) -> 0 | M2: =IF($L2<>1,0,SUMIFS('JLR Materials'!$E$2:$E$20001,'JLR Materials'!$A$2:$A$20001,$K2,'JLR Materials'!$C$2:$C$20001,IF(Settings!$B$2="","<>",Settings!$B$2),'JLR Materials'!$D$2:$D$20001,IF(Settings!$B$4="","<>",Settings!$B$4))) -> 0 | N2: =IF($L2<>1,0,SUMIFS('JLR Materials'!$F$2:$F$20001,'JLR Materials'!$A$2:$A$20001,$K2,'JLR Materials'!$C$2:$C$20001,IF(Settings!$B$2="","<>",Settings!$B$2),'JLR Materials'!$D$2:$D$20001,IF(Settings!$B$4="","<>",Settings!$B$4))) -> 0 | O2: =IF($N2=0,0,IF(Settings!$B$5="percent",$M2*$N2/100,$N2)) -> 0 | P2: =IF($L2<>1,0,SUMIFS('JLR Materials'!$G$2:$G$20001,'JLR Materials'!$A$2:$A$20001,$K2,'JLR Materials'!$C$2:$C$20001,IF(Settings!$B$2="","<>",Settings!$B$2),'JLR Materials'!$D$2:$D$20001,IF(Settings!$B$4="","<>",Settings!$B$4))) -> 0 | Q2: LME + UK processor premium, Jun 2026. Index-anchored 2026-07 refresh. | Refresh 2026-09: −£0.060/kg from 0.97kg al £2.910→£2.849/kg; premiums held | R2: 2026-09
A3: mat-steel1045 | B3: 1045 / C45 / 080M46 (Medium-Carbon Steel) | C3: Carbon Steel | D3: =IF($M3>0,$M3,0.95) -> 0.95 | E3: =IF($O3>0,$O3,0.22) -> 0.22 | F3: 7850 | G3: UK | H3: =IF($M3>0,IF($L3<>1,$R3,IFERROR(INDEX('JLR Materials'!$D$2:$D$20001,MATCH($K3,'JLR Materials'!$A$2:$A$20001,0)),$R3)),$R3) -> 2026-09 | I3: =IF($M3>0,"JLR rate card — material code "&$K3,$Q3) -> UK steel stockholder, Jun 2026. Index-anchored 2026-07 refresh. | Refresh 2026-09: INDEX FLAT — Index flat: Kallanish N-Europe wire rod ’stable’ (Jun 2026), ’decrease slightly’ (Jul), ’remain stable’ / ’flat’ (Sep 2026) — carbon and alloy bar unchanged. | J3: Medium | K3: =IFERROR(INDEX(Mapping!$C$2:$C$549,MATCH($A3,Mapping!$A$2:$A$549,0)),"") | L3: =IF($K3="",0,COUNTIFS('JLR Materials'!$A$2:$A$20001,$K3,'JLR Materials'!$C$2:$C$20001,IF(Settings!$B$2="","<>",Settings!$B$2),'JLR Materials'!$D$2:$D$20001,IF(Settings!$B$4="","<>",Settings!$B$4))) -> 0 | M3: =IF($L3<>1,0,SUMIFS('JLR Materials'!$E$2:$E$20001,'JLR Materials'!$A$2:$A$20001,$K3,'JLR Materials'!$C$2:$C$20001,IF(Settings!$B$2="","<>",Settings!$B$2),'JLR Materials'!$D$2:$D$20001,IF(Settings!$B$4="","<>",Settings!$B$4))) -> 0 | N3: =IF($L3<>1,0,SUMIFS('JLR Materials'!$F$2:$F$20001,'JLR Materials'!$A$2:$A$20001,$K3,'JLR Materials'!$C$2:$C$20001,IF(Settings!$B$2="","<>",Settings!$B$2),'JLR Materials'!$D$2:$D$20001,IF(Settings!$B$4="","<>",Settings!$B$4))) -> 0 | O3: =IF($N3=0,0,IF(Settings!$B$5="percent",$M3*$N3/100,$N3)) -> 0 | P3: =IF($L3<>1,0,SUMIFS('JLR Materials'!$G$2:$G$20001,'JLR Materials'!$A$2:$A$20001,$K3,'JLR Materials'!$C$2:$C$20001,IF(Settings!$B$2="","<>",Settings!$B$2),'JLR Materials'!$D$2:$D$20001,IF(Settings!$B$4="","<>",Settings!$B$4))) -> 0 | Q3: UK steel stockholder, Jun 2026. Index-anchored 2026-07 refresh. | Refresh 2026-09: INDEX FLAT — Index flat: Kallanish N-Europe wire rod ’stable’ (Jun 2026), ’decrease slightly’ (Jul), ’remain stable’ / ’flat’ (Sep 2026) — carbon and alloy bar unchanged. | R3: 2026-09
A4: mat-ss316l | B4: 316L | C4: Stainless Steel | D4: =IF($M4>0,$M4,3.95) -> 3.95 | E4: =IF($O4>0,$O4,0.88) -> 0.88 | F4: 7990 | G4: UK | H4: =IF($M4>0,IF($L4<>1,$R4,IFERROR(INDEX('JLR Materials'!$D$2:$D$20001,MATCH($K4,'JLR Materials'!$A$2:$A$20001,0)),$R4)),$R4) -> 2026-09 | I4: =IF($M4>0,"JLR rate card — material code "&$K4,$Q4) -> UK stainless distributor, Jun 2026. Index-anchored 2026-07 refresh. | Refresh 2026-09: +£0.129/kg from 1kg ss_sur £2.037→£2.164/kg, 0.03kg ni £12.302→£12.378/kg; premiums held | J4: Medium | K4: =IFERROR(INDEX(Mapping!$C$2:$C$549,MATCH($A4,Mapping!$A$2:$A$549,0)),"") | L4: =IF($K4="",0,COUNTIFS('JLR Materials'!$A$2:$A$20001,$K4,'JLR Materials'!$C$2:$C$20001,IF(Settings!$B$2="","<>",Settings!$B$2),'JLR Materials'!$D$2:$D$20001,IF(Settings!$B$4="","<>",Settings!$B$4))) -> 0 | M4: =IF($L4<>1,0,SUMIFS('JLR Materials'!$E$2:$E$20001,'JLR Materials'!$A$2:$A$20001,$K4,'JLR Materials'!$C$2:$C$20001,IF(Settings!$B$2="","<>",Settings!$B$2),'JLR Materials'!$D$2:$D$20001,IF(Settings!$B$4="","<>",Settings!$B$4))) -> 0 | N4: =IF($L4<>1,0,SUMIFS('JLR Materials'!$F$2:$F$20001,'JLR Materials'!$A$2:$A$20001,$K4,'JLR Materials'!$C$2:$C$20001,IF(Settings!$B$2="","<>",Settings!$B$2),'JLR Materials'!$D$2:$D$20001,IF(Settings!$B$4="","<>",Settings!$B$4))) -> 0 | O4: =IF($N4=0,0,IF(Settings!$B$5="percent",$M4*$N4/100,$N4)) -> 0 | P4: =IF($L4<>1,0,SUMIFS('JLR Materials'!$G$2:$G$20001,'JLR Materials'!$A$2:$A$20001,$K4,'JLR Materials'!$C$2:$C$20001,IF(Settings!$B$2="","<>",Settings!$B$2),'JLR Materials'!$D$2:$D$20001,IF(Settings!$B$4="","<>",Settings!$B$4))) -> 0 | Q4: UK stainless distributor, Jun 2026. Index-anchored 2026-07 refresh. | Refresh 2026-09: +£0.129/kg from 1kg ss_sur £2.037→£2.164/kg, 0.03kg ni £12.302→£12.378/kg; premiums held | R4: 2026-09
A5: mat-steel4140 | B5: 4140 / 42CrMo4 / EN19 (Chromoly Alloy Steel) | C5: Alloy Steel | D5: =IF($M5>0,$M5,1.21) -> 1.21 | E5: =IF($O5>0,$O5,0.22) -> 0.22 | F5: 7850 | G5: UK | H5: =IF($M5>0,IF($L5<>1,$R5,IFERROR(INDEX('JLR Materials'!$D$2:$D$20001,MATCH($K5,'JLR Materials'!$A$2:$A$20001,0)),$R5)),$R5) -> 2026-09 | I5: =IF($M5>0,"JLR rate card — material code "&$K5,$Q5) -> UK steel stockholder, Jun 2026. Index-anchored 2026-07 refresh. | Refresh 2026-09: INDEX FLAT — Index flat: Kallanish N-Europe wire rod ’stable’ (Jun 2026), ’decrease slightly’ (Jul), ’remain stable’ / ’flat’ (Sep 2026) — carbon and alloy bar unchanged. | J5: Medium | K5: =IFERROR(INDEX(Mapping!$C$2:$C$549,MATCH($A5,Mapping!$A$2:$A$549,0)),"") | L5: =IF($K5="",0,COUNTIFS('JLR Materials'!$A$2:$A$20001,$K5,'JLR Materials'!$C$2:$C$20001,IF(Settings!$B$2="","<>",Settings!$B$2),'JLR Materials'!$D$2:$D$20001,IF(Settings!$B$4="","<>",Settings!$B$4))) -> 0 | M5: =IF($L5<>1,0,SUMIFS('JLR Materials'!$E$2:$E$20001,'JLR Materials'!$A$2:$A$20001,$K5,'JLR Materials'!$C$2:$C$20001,IF(Settings!$B$2="","<>",Settings!$B$2),'JLR Materials'!$D$2:$D$20001,IF(Settings!$B$4="","<>",Settings!$B$4))) -> 0 | N5: =IF($L5<>1,0,SUMIFS('JLR Materials'!$F$2:$F$20001,'JLR Materials'!$A$2:$A$20001,$K5,'JLR Materials'!$C$2:$C$20001,IF(Settings!$B$2="","<>",Settings!$B$2),'JLR Materials'!$D$2:$D$20001,IF(Settings!$B$4="","<>",Settings!$B$4))) -> 0 | O5: =IF($N5=0,0,IF(Settings!$B$5="percent",$M5*$N5/100,$N5)) -> 0 | P5: =IF($L5<>1,0,SUMIFS('JLR Materials'!$G$2:$G$20001,'JLR Materials'!$A$2:$A$20001,$K5,'JLR Materials'!$C$2:$C$20001,IF(Settings!$B$2="","<>",Settings!$B$2),'JLR Materials'!$D$2:$D$20001,IF(Settings!$B$4="","<>",Settings!$B$4))) -> 0 | Q5: UK steel stockholder, Jun 2026. Index-anchored 2026-07 refresh. | Refresh 2026-09: INDEX FLAT — Index flat: Kallanish N-Europe wire rod ’stable’ (Jun 2026), ’decrease slightly’ (Jul), ’remain stable’ / ’flat’ (Sep 2026) — carbon and alloy bar unchanged. | R5: 2026-09
A6: mat-ti6al4v | B6: Ti-6Al-4V | C6: Titanium | D6: =IF($M6>0,$M6,47.13) -> 47.13 | E6: =IF($O6>0,$O6,15.88) -> 15.88 | F6: 4430 | G6: UK | H6: =IF($M6>0,IF($L6<>1,$R6,IFERROR(INDEX('JLR Materials'!$D$2:$D$20001,MATCH($K6,'JLR Materials'!$A$2:$A$20001,0)),$R6)),$R6) -> 2026-09 | I6: =IF($M6>0,"JLR rate card — material code "&$K6,$Q6) -> Titanium distributor UK, Jun 2026. Index-anchored 2026-07 refresh. | Refresh 2026-09: −£0.367/kg from 0.9kg ti £5.398→£4.989/kg; premiums held | J6: Low | K6: =IFERROR(INDEX(Mapping!$C$2:$C$549,MATCH($A6,Mapping!$A$2:$A$549,0)),"") | L6: =IF($K6="",0,COUNTIFS('JLR Materials'!$A$2:$A$20001,$K6,'JLR Materials'!$C$2:$C$20001,IF(Settings!$B$2="","<>",Settings!$B$2),'JLR Materials'!$D$2:$D$20001,IF(Settings!$B$4="","<>",Settings!$B$4))) -> 0 | M6: =IF($L6<>1,0,SUMIFS('JLR Materials'!$E$2:$E$20001,'JLR Materials'!$A$2:$A$20001,$K6,'JLR Materials'!$C$2:$C$20001,IF(Settings!$B$2="","<>",Settings!$B$2),'JLR Materials'!$D$2:$D$20001,IF(Settings!$B$4="","<>",Settings!$B$4))) -> 0 | N6: =IF($L6<>1,0,SUMIFS('JLR Materials'!$F$2:$F$20001,'JLR Materials'!$A$2:$A$20001,$K6,'JLR Materials'!$C$2:$C$20001,IF(Settings!$B$2="","<>",Settings!$B$2),'JLR Materials'!$D$2:$D$20001,IF(Settings!$B$4="","<>",Settings!$B$4))) -> 0 | O6: =IF($N6=0,0,IF(Settings!$B$5="percent",$M6*$N6/100,$N6)) -> 0 | P6: =IF($L6<>1,0,SUMIFS('JLR Materials'!$G$2:$G$20001,'JLR Materials'!$A$2:$A$20001,$K6,'JLR Materials'!$C$2:$C$20001,IF(Settings!$B$2="","<>",Settings!$B$2),'JLR Materials'!$D$2:$D$20001,IF(Settings!$B$4="","<>",Settings!$B$4))) -> 0 | Q6: Titanium distributor UK, Jun 2026. Index-anchored 2026-07 refresh. | Refresh 2026-09: −£0.367/kg from 0.9kg ti £5.398→£4.989/kg; premiums held | R6: 2026-09
A7: mat-virtual | B7: Virtual / Pass-through | C7: Virtual | D7: =IF($M7>0,$M7,1) -> 1 | E7: =IF($O7>0,$O7,0) -> 0 | F7: 1000 | G7: UK | H7: =IF($M7>0,IF($L7<>1,$R7,IFERROR(INDEX('JLR Materials'!$D$2:$D$20001,MATCH($K7,'JLR Materials'!$A$2:$A$20001,0)),$R7)),$R7) -> 2026-06-14 | I7: =IF($M7>0,"JLR rate card — material code "&$K7,$Q7) -> Placeholder for directCost modules (painting, BIW, PCB, PCBA). Price is irrelevant — directCost overrides. | J7: Medium | K7: =IFERROR(INDEX(Mapping!$C$2:$C$549,MATCH($A7,Mapping!$A$2:$A$549,0)),"") | L7: =IF($K7="",0,COUNTIFS('JLR Materials'!$A$2:$A$20001,$K7,'JLR Materials'!$C$2:$C$20001,IF(Settings!$B$2="","<>",Settings!$B$2),'JLR Materials'!$D$2:$D$20001,IF(Settings!$B$4="","<>",Settings!$B$4))) -> 0 | M7: =IF($L7<>1,0,SUMIFS('JLR Materials'!$E$2:$E$20001,'JLR Materials'!$A$2:$A$20001,$K7,'JLR Materials'!$C$2:$C$20001,IF(Settings!$B$2="","<>",Settings!$B$2),'JLR Materials'!$D$2:$D$20001,IF(Settings!$B$4="","<>",Settings!$B$4))) -> 0 | N7: =IF($L7<>1,0,SUMIFS('JLR Materials'!$F$2:$F$20001,'JLR Materials'!$A$2:$A$20001,$K7,'JLR Materials'!$C$2:$C$20001,IF(Settings!$B$2="","<>",Settings!$B$2),'JLR Materials'!$D$2:$D$20001,IF(Settings!$B$4="","<>",Settings!$B$4))) -> 0 | O7: =IF($N7=0,0,IF(Settings!$B$5="percent",$M7*$N7/100,$N7)) -> 0 | P7: =IF($L7<>1,0,SUMIFS('JLR Materials'!$G$2:$G$20001,'JLR Materials'!$A$2:$A$20001,$K7,'JLR Materials'!$C$2:$C$20001,IF(Settings!$B$2="","<>",Settings!$B$2),'JLR Materials'!$D$2:$D$20001,IF(Settings!$B$4="","<>",Settings!$B$4))) -> 0 | Q7: Placeholder for directCost modules (painting, BIW, PCB, PCBA). Price is irrelevant — directCost overrides. | R7: 2026-06-14
A8: mat-en8 | B8: EN8 / 080M40 (Medium Carbon) | C8: Carbon Steel | D8: =IF($M8>0,$M8,0.98) -> 0.98 | E8: =IF($O8>0,$O8,0.22) -> 0.22 | F8: 7850 | G8: UK | H8: =IF($M8>0,IF($L8<>1,$R8,IFERROR(INDEX('JLR Materials'!$D$2:$D$20001,MATCH($K8,'JLR Materials'!$A$2:$A$20001,0)),$R8)),$R8) -> 2026-09 | I8: =IF($M8>0,"JLR rate card — material code "&$K8,$Q8) -> Index-anchored 2026-07 refresh. General medium-carbon machining bar — shafts, studs, general engineering. | Refresh 2026-09: INDEX FLAT — Index flat: Kallanish N-Europe wire rod ’stable’ (Jun 2026), ’decrease slightly’ (Jul), ’remain stable’ / ’flat’ (Sep 2026) — carbon and alloy bar unchanged. | J8: Medium | K8: =IFERROR(INDEX(Mapping!$C$2:$C$549,MATCH($A8,Mapping!$A$2:$A$549,0)),"") | L8: =IF($K8="",0,COUNTIFS('JLR Materials'!$A$2:$A$20001,$K8,'JLR Materials'!$C$2:$C$20001,IF(Settings!$B$2="","<>",Settings!$B$2),'JLR Materials'!$D$2:$D$20001,IF(Settings!$B$4="","<>",Settings!$B$4))) -> 0 | M8: =IF($L8<>1,0,SUMIFS('JLR Materials'!$E$2:$E$20001,'JLR Materials'!$A$2:$A$20001,$K8,'JLR Materials'!$C$2:$C$20001,IF(Settings!$B$2="","<>",Settings!$B$2),'JLR Materials'!$D$2:$D$20001,IF(Settings!$B$4="","<>",Settings!$B$4))) -> 0 | N8: =IF($L8<>1,0,SUMIFS('JLR Materials'!$F$2:$F$20001,'JLR Materials'!$A$2:$A$20001,$K8,'JLR Materials'!$C$2:$C$20001,IF(Settings!$B$2="","<>",Settings!$B$2),'JLR Materials'!$D$2:$D$20001,IF(Settings!$B$4="","<>",Settings!$B$4))) -> 0 | O8: =IF($N8=0,0,IF(Settings!$B$5="percent",$M8*$N8/100,$N8)) -> 0 | P8: =IF($L8<>1,0,SUMIFS('JLR Materials'!$G$2:$G$20001,'JLR Materials'!$A$2:$A$20001,$K8,'JLR Materials'!$C$2:$C$20001,IF(Settings!$B$2="","<>",Settings!$B$2),'JLR Materials'!$D$2:$D$20001,IF(Settings!$B$4="","<>",Settings!$B$4))) -> 0 | Q8: Index-anchored 2026-07 refresh. General medium-carbon machining bar — shafts, studs, general engineering. | Refresh 2026-09: INDEX FLAT — Index flat: Kallanish N-Europe wire rod ’stable’ (Jun 2026), ’decrease slightly’ (Jul), ’remain stable’ / ’flat’ (Sep 2026) — carbon and alloy bar unchanged. | R8: 2026-09
A9: mat-ss304-bar | B9: 304 Stainless Bar | C9: Stainless Steel | D9: =IF($M9>0,$M9,3.53) -> 3.53 | E9: =IF($O9>0,$O9,0.83) -> 0.83 | F9: 8000 | G9: UK | H9: =IF($M9>0,IF($L9<>1,$R9,IFERROR(INDEX('JLR Materials'!$D$2:$D$20001,MATCH($K9,'JLR Materials'!$A$2:$A$20001,0)),$R9)),$R9) -> 2026-09 | I9: =IF($M9>0,"JLR rate card — material code "&$K9,$Q9) -> Index-anchored 2026-07 refresh. General austenitic machining bar — fittings, shafts, food/chemical. | Refresh 2026-09: +£0.127/kg from 1kg ss_sur £2.037→£2.164/kg; premiums held | J9: Medium | K9: =IFERROR(INDEX(Mapping!$C$2:$C$549,MATCH($A9,Mapping!$A$2:$A$549,0)),"") | L9: =IF($K9="",0,COUNTIFS('JLR Materials'!$A$2:$A$20001,$K9,'JLR Materials'!$C$2:$C$20001,IF(Settings!$B$2="","<>",Settings!$B$2),'JLR Materials'!$D$2:$D$20001,IF(Settings!$B$4="","<>",Settings!$B$4))) -> 0 | M9: =IF($L9<>1,0,SUMIFS('JLR Materials'!$E$2:$E$20001,'JLR Materials'!$A$2:$A$20001,$K9,'JLR Materials'!$C$2:$C$20001,IF(Settings!$B$2="","<>",Settings!$B$2),'JLR Materials'!$D$2:$D$20001,IF(Settings!$B$4="","<>",Settings!$B$4))) -> 0 | N9: =IF($L9<>1,0,SUMIFS('JLR Materials'!$F$2:$F$20001,'JLR Materials'!$A$2:$A$20001,$K9,'JLR Materials'!$C$2:$C$20001,IF(Settings!$B$2="","<>",Settings!$B$2),'JLR Materials'!$D$2:$D$20001,IF(Settings!$B$4="","<>",Settings!$B$4))) -> 0 | O9: =IF($N9=0,0,IF(Settings!$B$5="percent",$M9*$N9/100,$N9)) -> 0 | P9: =IF($L9<>1,0,SUMIFS('JLR Materials'!$G$2:$G$20001,'JLR Materials'!$A$2:$A$20001,$K9,'JLR Materials'!$C$2:$C$20001,IF(Settings!$B$2="","<>",Settings!$B$2),'JLR Materials'!$D$2:$D$20001,IF(Settings!$B$4="","<>",Settings!$B$4))) -> 0 | Q9: Index-anchored 2026-07 refresh. General austenitic machining bar — fittings, shafts, food/chemical. | Refresh 2026-09: +£0.127/kg from 1kg ss_sur £2.037→£2.164/kg; premiums held | R9: 2026-09
A10: mat-ss303 | B10: 303 Free-Machining Stainless Bar | C10: Stainless Steel | D10: =IF($M10>0,$M10,3.83) -> 3.83 | E10: =IF($O10>0,$O10,0.83) -> 0.83 | F10: 8000 | G10: UK | H10: =IF($M10>0,IF($L10<>1,$R10,IFERROR(INDEX('JLR Materials'!$D$2:$D$20001,MATCH($K10,'JLR Materials'!$A$2:$A$20001,0)),$R10)),$R10) -> 2026-09 | I10: =IF($M10>0,"JLR rate card — material code "&$K10,$Q10) -> Index-anchored 2026-07 refresh. Sulphur-added free-machining austenitic — high-volume turned parts, fasteners. | Refresh 2026-09: +£0.127/kg from 1kg ss_sur £2.037→£2.164/kg; premiums held | J10: Medium | K10: =IFERROR(INDEX(Mapping!$C$2:$C$549,MATCH($A10,Mapping!$A$2:$A$549,0)),"") | L10: =IF($K10="",0,COUNTIFS('JLR Materials'!$A$2:$A$20001,$K10,'JLR Materials'!$C$2:$C$20001,IF(Settings!$B$2="","<>",Settings!$B$2),'JLR Materials'!$D$2:$D$20001,IF(Settings!$B$4="","<>",Settings!$B$4))) -> 0 | M10: =IF($L10<>1,0,SUMIFS('JLR Materials'!$E$2:$E$20001,'JLR Materials'!$A$2:$A$20001,$K10,'JLR Materials'!$C$2:$C$20001,IF(Settings!$B$2="","<>",Settings!$B$2),'JLR Materials'!$D$2:$D$20001,IF(Settings!$B$4="","<>",Settings!$B$4))) -> 0 | N10: =IF($L10<>1,0,SUMIFS('JLR Materials'!$F$2:$F$20001,'JLR Materials'!$A$2:$A$20001,$K10,'JLR Materials'!$C$2:$C$20001,IF(Settings!$B$2="","<>",Settings!$B$2),'JLR Materials'!$D$2:$D$20001,IF(Settings!$B$4="","<>",Settings!$B$4))) -> 0 | O10: =IF($N10=0,0,IF(Settings!$B$5="percent",$M10*$N10/100,$N10)) -> 0 | P10: =IF($L10<>1,0,SUMIFS('JLR Materials'!$G$2:$G$20001,'JLR Materials'!$A$2:$A$20001,$K10,'JLR Materials'!$C$2:$C$20001,IF(Settings!$B$2="","<>",Settings!$B$2),'JLR Materials'!$D$2:$D$20001,IF(Settings!$B$4="","<>",Settings!$B$4))) -> 0 | Q10: Index-anchored 2026-07 refresh. Sulphur-added free-machining austenitic — high-volume turned parts, fasteners. | Refresh 2026-09: +£0.127/kg from 1kg ss_sur £2.037→£2.164/kg; premiums held | R10: 2026-09
A11: mat-al6082-bar | B11: 6082-T6 Aluminium Bar | C11: Aluminium | D11: =IF($M11>0,$M11,3.49) -> 3.49 | E11: =IF($O11>0,$O11,0.54) -> 0.54 | F11: 2700 | G11: UK | H11: =IF($M11>0,IF($L11<>1,$R11,IFERROR(INDEX('JLR Materials'!$D$2:$D$20001,MATCH($K11,'JLR Materials'!$A$2:$A$20001,0)),$R11)),$R11) -> 2026-09 | I11: =IF($M11>0,"JLR rate card — material code "&$K11,$Q11) -> Index-anchored 2026-07 refresh. Structural 6xxx machining bar/plate — brackets, jigs, structural parts. | Refresh 2026-09: −£0.060/kg from 0.97kg al £2.910→£2.849/kg; premiums held | J11: Medium | K11: =IFERROR(INDEX(Mapping!$C$2:$C$549,MATCH($A11,Mapping!$A$2:$A$549,0)),"") | L11: =IF($K11="",0,COUNTIFS('JLR Materials'!$A$2:$A$20001,$K11,'JLR Materials'!$C$2:$C$20001,IF(Settings!$B$2="","<>",Settings!$B$2),'JLR Materials'!$D$2:$D$20001,IF(Settings!$B$4="","<>",Settings!$B$4))) -> 0 | M11: =IF($L11<>1,0,SUMIFS('JLR Materials'!$E$2:$E$20001,'JLR Materials'!$A$2:$A$20001,$K11,'JLR Materials'!$C$2:$C$20001,IF(Settings!$B$2="","<>",Settings!$B$2),'JLR Materials'!$D$2:$D$20001,IF(Settings!$B$4="","<>",Settings!$B$4))) -> 0 | N11: =IF($L11<>1,0,SUMIFS('JLR Materials'!$F$2:$F$20001,'JLR Materials'!$A$2:$A$20001,$K11,'JLR Materials'!$C$2:$C$20001,IF(Settings!$B$2="","<>",Settings!$B$2),'JLR Materials'!$D$2:$D$20001,IF(Settings!$B$4="","<>",Settings!$B$4))) -> 0 | O11: =IF($N11=0,0,IF(Settings!$B$5="percent",$M11*$N11/100,$N11)) -> 0 | P11: =IF($L11<>1,0,SUMIFS('JLR Materials'!$G$2:$G$20001,'JLR Materials'!$A$2:$A$20001,$K11,'JLR Materials'!$C$2:$C$20001,IF(Settings!$B$2="","<>",Settings!$B$2),'JLR Materials'!$D$2:$D$20001,IF(Settings!$B$4="","<>",Settings!$B$4))) -> 0 | Q11: Index-anchored 2026-07 refresh. Structural 6xxx machining bar/plate — brackets, jigs, structural parts. | Refresh 2026-09: −£0.060/kg from 0.97kg al £2.910→£2.849/kg; premiums held | R11: 2026-09
A12: mat-al2011 | B12: 2011-T3 Free-Machining Al Bar | C12: Aluminium | D12: =IF($M12>0,$M12,3.93) -> 3.93 | E12: =IF($O12>0,$O12,0.55) -> 0.55 | F12: 2830 | G12: UK | H12: =IF($M12>0,IF($L12<>1,$R12,IFERROR(INDEX('JLR Materials'!$D$2:$D$20001,MATCH($K12,'JLR Materials'!$A$2:$A$20001,0)),$R12)),$R12) -> 2026-09 | I12: =IF($M12>0,"JLR rate card — material code "&$K12,$Q12) -> Index-anchored 2026-07 refresh. Free-machining Al-Cu-Pb — high-speed screw-machine parts, fittings. | Refresh 2026-09: −£0.022/kg from 0.93kg al £2.910→£2.849/kg, 0.05kg cu £10.070→£10.768/kg; premiums held | J12: Low | K12: =IFERROR(INDEX(Mapping!$C$2:$C$549,MATCH($A12,Mapping!$A$2:$A$549,0)),"") | L12: =IF($K12="",0,COUNTIFS('JLR Materials'!$A$2:$A$20001,$K12,'JLR Materials'!$C$2:$C$20001,IF(Settings!$B$2="","<>",Settings!$B$2),'JLR Materials'!$D$2:$D$20001,IF(Settings!$B$4="","<>",Settings!$B$4))) -> 0 | M12: =IF($L12<>1,0,SUMIFS('JLR Materials'!$E$2:$E$20001,'JLR Materials'!$A$2:$A$20001,$K12,'JLR Materials'!$C$2:$C$20001,IF(Settings!$B$2="","<>",Settings!$B$2),'JLR Materials'!$D$2:$D$20001,IF(Settings!$B$4="","<>",Settings!$B$4))) -> 0 | N12: =IF($L12<>1,0,SUMIFS('JLR Materials'!$F$2:$F$20001,'JLR Materials'!$A$2:$A$20001,$K12,'JLR Materials'!$C$2:$C$20001,IF(Settings!$B$2="","<>",Settings!$B$2),'JLR Materials'!$D$2:$D$20001,IF(Settings!$B$4="","<>",Settings!$B$4))) -> 0 | O12: =IF($N12=0,0,IF(Settings!$B$5="percent",$M12*$N12/100,$N12)) -> 0 | P12: =IF($L12<>1,0,SUMIFS('JLR Materials'!$G$2:$G$20001,'JLR Materials'!$A$2:$A$20001,$K12,'JLR Materials'!$C$2:$C$20001,IF(Settings!$B$2="","<>",Settings!$B$2),'JLR Materials'!$D$2:$D$20001,IF(Settings!$B$4="","<>",Settings!$B$4))) -> 0 | Q12: Index-anchored 2026-07 refresh. Free-machining Al-Cu-Pb — high-speed screw-machine parts, fittings. | Refresh 2026-09: −£0.022/kg from 0.93kg al £2.910→£2.849/kg, 0.05kg cu £10.070→£10.768/kg; premiums held | R12: 2026-09
A13: mat-brass-cz121 | B13: CZ121 / CW614N Free-Machining Brass | C13: Copper Alloy | D13: =IF($M13>0,$M13,7.7) -> 7.7 | E13: =IF($O13>0,$O13,3.3) -> 3.3 | F13: 8490 | G13: UK | H13: =IF($M13>0,IF($L13<>1,$R13,IFERROR(INDEX('JLR Materials'!$D$2:$D$20001,MATCH($K13,'JLR Materials'!$A$2:$A$20001,0)),$R13)),$R13) -> 2026-09 | I13: =IF($M13>0,"JLR rate card — material code "&$K13,$Q13) -> Index-anchored 2026-07 refresh. Standard free-machining brass bar — fittings, valve parts, connectors. | Refresh 2026-09: +£0.697/kg from 0.58kg cu £10.070→£10.768/kg, 0.39kg zn £2.164→£2.913/kg, 0.03kg pb £1.442→£1.438/kg; premiums held | J13: Low | K13: =IFERROR(INDEX(Mapping!$C$2:$C$549,MATCH($A13,Mapping!$A$2:$A$549,0)),"") | L13: =IF($K13="",0,COUNTIFS('JLR Materials'!$A$2:$A$20001,$K13,'JLR Materials'!$C$2:$C$20001,IF(Settings!$B$2="","<>",Settings!$B$2),'JLR Materials'!$D$2:$D$20001,IF(Settings!$B$4="","<>",Settings!$B$4))) -> 0 | M13: =IF($L13<>1,0,SUMIFS('JLR Materials'!$E$2:$E$20001,'JLR Materials'!$A$2:$A$20001,$K13,'JLR Materials'!$C$2:$C$20001,IF(Settings!$B$2="","<>",Settings!$B$2),'JLR Materials'!$D$2:$D$20001,IF(Settings!$B$4="","<>",Settings!$B$4))) -> 0 | N13: =IF($L13<>1,0,SUMIFS('JLR Materials'!$F$2:$F$20001,'JLR Materials'!$A$2:$A$20001,$K13,'JLR Materials'!$C$2:$C$20001,IF(Settings!$B$2="","<>",Settings!$B$2),'JLR Materials'!$D$2:$D$20001,IF(Settings!$B$4="","<>",Settings!$B$4))) -> 0 | O13: =IF($N13=0,0,IF(Settings!$B$5="percent",$M13*$N13/100,$N13)) -> 0 | P13: =IF($L13<>1,0,SUMIFS('JLR Materials'!$G$2:$G$20001,'JLR Materials'!$A$2:$A$20001,$K13,'JLR Materials'!$C$2:$C$20001,IF(Settings!$B$2="","<>",Settings!$B$2),'JLR Materials'!$D$2:$D$20001,IF(Settings!$B$4="","<>",Settings!$B$4))) -> 0 | Q13: Index-anchored 2026-07 refresh. Standard free-machining brass bar — fittings, valve parts, connectors. | Refresh 2026-09: +£0.697/kg from 0.58kg cu £10.070→£10.768/kg, 0.39kg zn £2.164→£2.913/kg, 0.03kg pb £1.442→£1.438/kg; premiums held | R13: 2026-09
A14: mat-bronze-pb1 | B14: PB1 Phosphor Bronze Bar | C14: Copper Alloy | D14: =IF($M14>0,$M14,13.91) -> 13.91 | E14: =IF($O14>0,$O14,4.23) -> 4.23 | F14: 8800 | G14: UK | H14: =IF($M14>0,IF($L14<>1,$R14,IFERROR(INDEX('JLR Materials'!$D$2:$D$20001,MATCH($K14,'JLR Materials'!$A$2:$A$20001,0)),$R14)),$R14) -> 2026-09 | I14: =IF($M14>0,"JLR rate card — material code "&$K14,$Q14) -> Index-anchored 2026-07 refresh. Phosphor bronze bar — bearings, bushes, worm wheels, high-load sliding. | Refresh 2026-09: +£4.710/kg from 0.89kg cu £10.070→£10.768/kg, 0.105kg sn £38.211→£41.201/kg, floored at commodity content £13.91/kg (previous level was below the metal it contains); premiums held | J14: Low | K14: =IFERROR(INDEX(Mapping!$C$2:$C$549,MATCH($A14,Mapping!$A$2:$A$549,0)),"") | L14: =IF($K14="",0,COUNTIFS('JLR Materials'!$A$2:$A$20001,$K14,'JLR Materials'!$C$2:$C$20001,IF(Settings!$B$2="","<>",Settings!$B$2),'JLR Materials'!$D$2:$D$20001,IF(Settings!$B$4="","<>",Settings!$B$4))) -> 0 | M14: =IF($L14<>1,0,SUMIFS('JLR Materials'!$E$2:$E$20001,'JLR Materials'!$A$2:$A$20001,$K14,'JLR Materials'!$C$2:$C$20001,IF(Settings!$B$2="","<>",Settings!$B$2),'JLR Materials'!$D$2:$D$20001,IF(Settings!$B$4="","<>",Settings!$B$4))) -> 0 | N14: =IF($L14<>1,0,SUMIFS('JLR Materials'!$F$2:$F$20001,'JLR Materials'!$A$2:$A$20001,$K14,'JLR Materials'!$C$2:$C$20001,IF(Settings!$B$2="","<>",Settings!$B$2),'JLR Materials'!$D$2:$D$20001,IF(Settings!$B$4="","<>",Settings!$B$4))) -> 0 | O14: =IF($N14=0,0,IF(Settings!$B$5="percent",$M14*$N14/100,$N14)) -> 0 | P14: =IF($L14<>1,0,SUMIFS('JLR Materials'!$G$2:$G$20001,'JLR Materials'!$A$2:$A$20001,$K14,'JLR Materials'!$C$2:$C$20001,IF(Settings!$B$2="","<>",Settings!$B$2),'JLR Materials'!$D$2:$D$20001,IF(Settings!$B$4="","<>",Settings!$B$4))) -> 0 | Q14: Index-anchored 2026-07 refresh. Phosphor bronze bar — bearings, bushes, worm wheels, high-load sliding. | Refresh 2026-09: +£4.710/kg from 0.89kg cu £10.070→£10.768/kg, 0.105kg sn £38.211→£41.201/kg, floored at commodity content £13.91/kg (previous level was below the metal it contains); premiums held | R14: 2026-09
A15: mat-pom-c | B15: POM-C (Acetal / Delrin Stock) | C15: Engineering Plastic (Stock) | D15: =IF($M15>0,$M15,3.1) -> 3.1 | E15: =IF($O15>0,$O15,0.1) -> 0.1 | F15: 1410 | G15: UK | H15: =IF($M15>0,IF($L15<>1,$R15,IFERROR(INDEX('JLR Materials'!$D$2:$D$20001,MATCH($K15,'JLR Materials'!$A$2:$A$20001,0)),$R15)),$R15) -> 2026-09 | I15: =IF($M15>0,"JLR rate card — material code "&$K15,$Q15) -> Index-anchored 2026-07. Acetal copolymer rod/sheet — precision gears, bushes, manifolds; excellent machinability. | Refresh 2026-09: NOT SOURCED — pom: Not sourced this period: engineering resin prices are paywalled (PIE/ICIS). Direction only: PC rising through Aug 2026, PA6 rebounding, PA66 under pressure, PET declining — no like-for-like June→Sep figures. Held at the June 2026 price. | J15: Medium | K15: =IFERROR(INDEX(Mapping!$C$2:$C$549,MATCH($A15,Mapping!$A$2:$A$549,0)),"") | L15: =IF($K15="",0,COUNTIFS('JLR Materials'!$A$2:$A$20001,$K15,'JLR Materials'!$C$2:$C$20001,IF(Settings!$B$2="","<>",Settings!$B$2),'JLR Materials'!$D$2:$D$20001,IF(Settings!$B$4="","<>",Settings!$B$4))) -> 0 | M15: =IF($L15<>1,0,SUMIFS('JLR Materials'!$E$2:$E$20001,'JLR Materials'!$A$2:$A$20001,$K15,'JLR Materials'!$C$2:$C$20001,IF(Settings!$B$2="","<>",Settings!$B$2),'JLR Materials'!$D$2:$D$20001,IF(Settings!$B$4="","<>",Settings!$B$4))) -> 0 | N15: =IF($L15<>1,0,SUMIFS('JLR Materials'!$F$2:$F$20001,'JLR Materials'!$A$2:$A$20001,$K15,'JLR Materials'!$C$2:$C$20001,IF(Settings!$B$2="","<>",Settings!$B$2),'JLR Materials'!$D$2:$D$20001,IF(Settings!$B$4="","<>",Settings!$B$4))) -> 0 | O15: =IF($N15=0,0,IF(Settings!$B$5="percent",$M15*$N15/100,$N15)) -> 0 | P15: =IF($L15<>1,0,SUMIFS('JLR Materials'!$G$2:$G$20001,'JLR Materials'!$A$2:$A$20001,$K15,'JLR Materials'!$C$2:$C$20001,IF(Settings!$B$2="","<>",Settings!$B$2),'JLR Materials'!$D$2:$D$20001,IF(Settings!$B$4="","<>",Settings!$B$4))) -> 0 | Q15: Index-anchored 2026-07. Acetal copolymer rod/sheet — precision gears, bushes, manifolds; excellent machinability. | Refresh 2026-09: NOT SOURCED — pom: Not sourced this period: engineering resin prices are paywalled (PIE/ICIS). Direction only: PC rising through Aug 2026, PA6 rebounding, PA66 under pressure, PET declining — no like-for-like June→Sep figures. Held at the June 2026 price. | R15: 2026-09
A16: mat-pa6-cast | B16: Nylon 6 (Cast PA6 Stock) | C16: Engineering Plastic (Stock) | D16: =IF($M16>0,$M16,4.2) -> 4.2 | E16: =IF($O16>0,$O16,0.1) -> 0.1 | F16: 1150 | G16: UK | H16: =IF($M16>0,IF($L16<>1,$R16,IFERROR(INDEX('JLR Materials'!$D$2:$D$20001,MATCH($K16,'JLR Materials'!$A$2:$A$20001,0)),$R16)),$R16) -> 2026-09 | I16: =IF($M16>0,"JLR rate card — material code "&$K16,$Q16) -> Index-anchored 2026-07. Cast nylon rod/slab — wear pads, sprockets, rollers, guide rails. | Refresh 2026-09: NOT SOURCED — pa6: Not sourced this period: engineering resin prices are paywalled (PIE/ICIS). Direction only: PC rising through Aug 2026, PA6 rebounding, PA66 under pressure, PET declining — no like-for-like June→Sep figures. Held at the June 2026 price. | J16: Medium | K16: =IFERROR(INDEX(Mapping!$C$2:$C$549,MATCH($A16,Mapping!$A$2:$A$549,0)),"") | L16: =IF($K16="",0,COUNTIFS('JLR Materials'!$A$2:$A$20001,$K16,'JLR Materials'!$C$2:$C$20001,IF(Settings!$B$2="","<>",Settings!$B$2),'JLR Materials'!$D$2:$D$20001,IF(Settings!$B$4="","<>",Settings!$B$4))) -> 0 | M16: =IF($L16<>1,0,SUMIFS('JLR Materials'!$E$2:$E$20001,'JLR Materials'!$A$2:$A$20001,$K16,'JLR Materials'!$C$2:$C$20001,IF(Settings!$B$2="","<>",Settings!$B$2),'JLR Materials'!$D$2:$D$20001,IF(Settings!$B$4="","<>",Settings!$B$4))) -> 0 | N16: =IF($L16<>1,0,SUMIFS('JLR Materials'!$F$2:$F$20001,'JLR Materials'!$A$2:$A$20001,$K16,'JLR Materials'!$C$2:$C$20001,IF(Settings!$B$2="","<>",Settings!$B$2),'JLR Materials'!$D$2:$D$20001,IF(Settings!$B$4="","<>",Settings!$B$4))) -> 0 | O16: =IF($N16=0,0,IF(Settings!$B$5="percent",$M16*$N16/100,$N16)) -> 0 | P16: =IF($L16<>1,0,SUMIFS('JLR Materials'!$G$2:$G$20001,'JLR Materials'!$A$2:$A$20001,$K16,'JLR Materials'!$C$2:$C$20001,IF(Settings!$B$2="","<>",Settings!$B$2),'JLR Materials'!$D$2:$D$20001,IF(Settings!$B$4="","<>",Settings!$B$4))) -> 0 | Q16: Index-anchored 2026-07. Cast nylon rod/slab — wear pads, sprockets, rollers, guide rails. | Refresh 2026-09: NOT SOURCED — pa6: Not sourced this period: engineering resin prices are paywalled (PIE/ICIS). Direction only: PC rising through Aug 2026, PA6 rebounding, PA66 under pressure, PET declining — no like-for-like June→Sep figures. Held at the June 2026 price. | R16: 2026-09
A17: mat-ptfe | B17: PTFE (Virgin Stock) | C17: Engineering Plastic (Stock) | D17: =IF($M17>0,$M17,12.5) -> 12.5 | E17: =IF($O17>0,$O17,0.2) -> 0.2 | F17: 2170 | G17: UK | H17: =IF($M17>0,IF($L17<>1,$R17,IFERROR(INDEX('JLR Materials'!$D$2:$D$20001,MATCH($K17,'JLR Materials'!$A$2:$A$20001,0)),$R17)),$R17) -> 2026-09 | I17: =IF($M17>0,"JLR rate card — material code "&$K17,$Q17) -> Index-anchored 2026-07. Virgin PTFE rod/sheet — seals, insulators, chemical/low-friction parts. | Refresh 2026-09: SPECIALTY — no public market index for this grade; held at the June 2026 price — refresh by supplier quote | J17: Low | K17: =IFERROR(INDEX(Mapping!$C$2:$C$549,MATCH($A17,Mapping!$A$2:$A$549,0)),"") | L17: =IF($K17="",0,COUNTIFS('JLR Materials'!$A$2:$A$20001,$K17,'JLR Materials'!$C$2:$C$20001,IF(Settings!$B$2="","<>",Settings!$B$2),'JLR Materials'!$D$2:$D$20001,IF(Settings!$B$4="","<>",Settings!$B$4))) -> 0 | M17: =IF($L17<>1,0,SUMIFS('JLR Materials'!$E$2:$E$20001,'JLR Materials'!$A$2:$A$20001,$K17,'JLR Materials'!$C$2:$C$20001,IF(Settings!$B$2="","<>",Settings!$B$2),'JLR Materials'!$D$2:$D$20001,IF(Settings!$B$4="","<>",Settings!$B$4))) -> 0 | N17: =IF($L17<>1,0,SUMIFS('JLR Materials'!$F$2:$F$20001,'JLR Materials'!$A$2:$A$20001,$K17,'JLR Materials'!$C$2:$C$20001,IF(Settings!$B$2="","<>",Settings!$B$2),'JLR Materials'!$D$2:$D$20001,IF(Settings!$B$4="","<>",Settings!$B$4))) -> 0 | O17: =IF($N17=0,0,IF(Settings!$B$5="percent",$M17*$N17/100,$N17)) -> 0 | P17: =IF($L17<>1,0,SUMIFS('JLR Materials'!$G$2:$G$20001,'JLR Materials'!$A$2:$A$20001,$K17,'JLR Materials'!$C$2:$C$20001,IF(Settings!$B$2="","<>",Settings!$B$2),'JLR Materials'!$D$2:$D$20001,IF(Settings!$B$4="","<>",Settings!$B$4))) -> 0 | Q17: Index-anchored 2026-07. Virgin PTFE rod/sheet — seals, insulators, chemical/low-friction parts. | Refresh 2026-09: SPECIALTY — no public market index for this grade; held at the June 2026 price — refresh by supplier quote | R17: 2026-09
A18: mat-peek-stock | B18: PEEK (Unfilled Stock) | C18: Engineering Plastic (Stock) | D18: =IF($M18>0,$M18,95) -> 95 | E18: =IF($O18>0,$O18,0.5) -> 0.5 | F18: 1300 | G18: UK | H18: =IF($M18>0,IF($L18<>1,$R18,IFERROR(INDEX('JLR Materials'!$D$2:$D$20001,MATCH($K18,'JLR Materials'!$A$2:$A$20001,0)),$R18)),$R18) -> 2026-09 | I18: =IF($M18>0,"JLR rate card — material code "&$K18,$Q18) -> Index-anchored 2026-07. Unfilled PEEK rod/plate — high-temp/chemical machined parts, medical, aerospace. | Refresh 2026-09: SPECIALTY — no public market index for this grade; held at the June 2026 price — refresh by supplier quote | J18: Low | K18: =IFERROR(INDEX(Mapping!$C$2:$C$549,MATCH($A18,Mapping!$A$2:$A$549,0)),"") | L18: =IF($K18="",0,COUNTIFS('JLR Materials'!$A$2:$A$20001,$K18,'JLR Materials'!$C$2:$C$20001,IF(Settings!$B$2="","<>",Settings!$B$2),'JLR Materials'!$D$2:$D$20001,IF(Settings!$B$4="","<>",Settings!$B$4))) -> 0 | M18: =IF($L18<>1,0,SUMIFS('JLR Materials'!$E$2:$E$20001,'JLR Materials'!$A$2:$A$20001,$K18,'JLR Materials'!$C$2:$C$20001,IF(Settings!$B$2="","<>",Settings!$B$2),'JLR Materials'!$D$2:$D$20001,IF(Settings!$B$4="","<>",Settings!$B$4))) -> 0 | N18: =IF($L18<>1,0,SUMIFS('JLR Materials'!$F$2:$F$20001,'JLR Materials'!$A$2:$A$20001,$K18,'JLR Materials'!$C$2:$C$20001,IF(Settings!$B$2="","<>",Settings!$B$2),'JLR Materials'!$D$2:$D$20001,IF(Settings!$B$4="","<>",Settings!$B$4))) -> 0 | O18: =IF($N18=0,0,IF(Settings!$B$5="percent",$M18*$N18/100,$N18)) -> 0 | P18: =IF($L18<>1,0,SUMIFS('JLR Materials'!$G$2:$G$20001,'JLR Materials'!$A$2:$A$20001,$K18,'JLR Materials'!$C$2:$C$20001,IF(Settings!$B$2="","<>",Settings!$B$2),'JLR Materials'!$D$2:$D$20001,IF(Settings!$B$4="","<>",Settings!$B$4))) -> 0 | Q18: Index-anchored 2026-07. Unfilled PEEK rod/plate — high-temp/chemical machined parts, medical, aerospace. | Refresh 2026-09: SPECIALTY — no public market index for this grade; held at the June 2026 price — refresh by supplier quote | R18: 2026-09
A19: mat-acrylic-cast | B19: Cast Acrylic (PMMA Stock) | C19: Engineering Plastic (Stock) | D19: =IF($M19>0,$M19,4.8) -> 4.8 | E19: =IF($O19>0,$O19,0.05) -> 0.05 | F19: 1190 | G19: UK | H19: =IF($M19>0,IF($L19<>1,$R19,IFERROR(INDEX('JLR Materials'!$D$2:$D$20001,MATCH($K19,'JLR Materials'!$A$2:$A$20001,0)),$R19)),$R19) -> 2026-09 | I19: =IF($M19>0,"JLR rate card — material code "&$K19,$Q19) -> Index-anchored 2026-07. Cast acrylic sheet/rod — optical, signage, machined transparent parts. | Refresh 2026-09: NOT SOURCED — pmma: Not sourced this period: engineering resin prices are paywalled (PIE/ICIS). Direction only: PC rising through Aug 2026, PA6 rebounding, PA66 under pressure, PET declining — no like-for-like June→Sep figures. Held at the June 2026 price. | J19: Low | K19: =IFERROR(INDEX(Mapping!$C$2:$C$549,MATCH($A19,Mapping!$A$2:$A$549,0)),"") | L19: =IF($K19="",0,COUNTIFS('JLR Materials'!$A$2:$A$20001,$K19,'JLR Materials'!$C$2:$C$20001,IF(Settings!$B$2="","<>",Settings!$B$2),'JLR Materials'!$D$2:$D$20001,IF(Settings!$B$4="","<>",Settings!$B$4))) -> 0 | M19: =IF($L19<>1,0,SUMIFS('JLR Materials'!$E$2:$E$20001,'JLR Materials'!$A$2:$A$20001,$K19,'JLR Materials'!$C$2:$C$20001,IF(Settings!$B$2="","<>",Settings!$B$2),'JLR Materials'!$D$2:$D$20001,IF(Settings!$B$4="","<>",Settings!$B$4))) -> 0 | N19: =IF($L19<>1,0,SUMIFS('JLR Materials'!$F$2:$F$20001,'JLR Materials'!$A$2:$A$20001,$K19,'JLR Materials'!$C$2:$C$20001,IF(Settings!$B$2="","<>",Settings!$B$2),'JLR Materials'!$D$2:$D$20001,IF(Settings!$B$4="","<>",Settings!$B$4))) -> 0 | O19: =IF($N19=0,0,IF(Settings!$B$5="percent",$M19*$N19/100,$N19)) -> 0 | P19: =IF($L19<>1,0,SUMIFS('JLR Materials'!$G$2:$G$20001,'JLR Materials'!$A$2:$A$20001,$K19,'JLR Materials'!$C$2:$C$20001,IF(Settings!$B$2="","<>",Settings!$B$2),'JLR Materials'!$D$2:$D$20001,IF(Settings!$B$4="","<>",Settings!$B$4))) -> 0 | Q19: Index-anchored 2026-07. Cast acrylic sheet/rod — optical, signage, machined transparent parts. | Refresh 2026-09: NOT SOURCED — pmma: Not sourced this period: engineering resin prices are paywalled (PIE/ICIS). Direction only: PC rising through Aug 2026, PA6 rebounding, PA66 under pressure, PET declining — no like-for-like June→Sep figures. Held at the June 2026 price. | R19: 2026-09
A20: mat-uhmwpe | B20: UHMW-PE (Stock) | C20: Engineering Plastic (Stock) | D20: =IF($M20>0,$M20,3.4) -> 3.4 | E20: =IF($O20>0,$O20,0.08) -> 0.08 | F20: 940 | G20: UK | H20: =IF($M20>0,IF($L20<>1,$R20,IFERROR(INDEX('JLR Materials'!$D$2:$D$20001,MATCH($K20,'JLR Materials'!$A$2:$A$20001,0)),$R20)),$R20) -> 2026-09 | I20: =IF($M20>0,"JLR rate card — material code "&$K20,$Q20) -> Index-anchored 2026-07. Ultra-high-molecular-weight PE sheet — wear strips, chute liners, guides. | Refresh 2026-09: SPECIALTY — no public market index for this grade; held at the June 2026 price — refresh by supplier quote | J20: Low | K20: =IFERROR(INDEX(Mapping!$C$2:$C$549,MATCH($A20,Mapping!$A$2:$A$549,0)),"") | L20: =IF($K20="",0,COUNTIFS('JLR Materials'!$A$2:$A$20001,$K20,'JLR Materials'!$C$2:$C$20001,IF(Settings!$B$2="","<>",Settings!$B$2),'JLR Materials'!$D$2:$D$20001,IF(Settings!$B$4="","<>",Settings!$B$4))) -> 0 | M20: =IF($L20<>1,0,SUMIFS('JLR Materials'!$E$2:$E$20001,'JLR Materials'!$A$2:$A$20001,$K20,'JLR Materials'!$C$2:$C$20001,IF(Settings!$B$2="","<>",Settings!$B$2),'JLR Materials'!$D$2:$D$20001,IF(Settings!$B$4="","<>",Settings!$B$4))) -> 0 | N20: =IF($L20<>1,0,SUMIFS('JLR Materials'!$F$2:$F$20001,'JLR Materials'!$A$2:$A$20001,$K20,'JLR Materials'!$C$2:$C$20001,IF(Settings!$B$2="","<>",Settings!$B$2),'JLR Materials'!$D$2:$D$20001,IF(Settings!$B$4="","<>",Settings!$B$4))) -> 0 | O20: =IF($N20=0,0,IF(Settings!$B$5="percent",$M20*$N20/100,$N20)) -> 0 | P20: =IF($L20<>1,0,SUMIFS('JLR Materials'!$G$2:$G$20001,'JLR Materials'!$A$2:$A$20001,$K20,'JLR Materials'!$C$2:$C$20001,IF(Settings!$B$2="","<>",Settings!$B$2),'JLR Materials'!$D$2:$D$20001,IF(Settings!$B$4="","<>",Settings!$B$4))) -> 0 | Q20: Index-anchored 2026-07. Ultra-high-molecular-weight PE sheet — wear strips, chute liners, guides. | Refresh 2026-09: SPECIALTY — no public market index for this grade; held at the June 2026 price — refresh by supplier quote | R20: 2026-09
A21: mat-dc01 | B21: DC01 | C21: Mild Steel Sheet | D21: =IF($M21>0,$M21,0.91) -> 0.91 | E21: =IF($O21>0,$O21,0.21) -> 0.21 | F21: 7850 | G21: UK | H21: =IF($M21>0,IF($L21<>1,$R21,IFERROR(INDEX('JLR Materials'!$D$2:$D$20001,MATCH($K21,'JLR Materials'!$A$2:$A$20001,0)),$R21)),$R21) -> 2026-09 | I21: =IF($M21>0,"JLR rate card — material code "&$K21,$Q21) -> UK CR mild sheet, delivered small-lot. Index-anchored: CRC €781/t → £0.67/kg mill + £0.19/kg stockholder premium. Basis: Fastmarkets EU HRC €691/t May-26 +€90 CRC, FX 0.855. Yield ~140 MPa. | Refresh 2026-09: +£0.049/kg from 1kg crc £0.668→£0.717/kg; premiums held | J21: Medium | K21: =IFERROR(INDEX(Mapping!$C$2:$C$549,MATCH($A21,Mapping!$A$2:$A$549,0)),"") | L21: =IF($K21="",0,COUNTIFS('JLR Materials'!$A$2:$A$20001,$K21,'JLR Materials'!$C$2:$C$20001,IF(Settings!$B$2="","<>",Settings!$B$2),'JLR Materials'!$D$2:$D$20001,IF(Settings!$B$4="","<>",Settings!$B$4))) -> 0 | M21: =IF($L21<>1,0,SUMIFS('JLR Materials'!$E$2:$E$20001,'JLR Materials'!$A$2:$A$20001,$K21,'JLR Materials'!$C$2:$C$20001,IF(Settings!$B$2="","<>",Settings!$B$2),'JLR Materials'!$D$2:$D$20001,IF(Settings!$B$4="","<>",Settings!$B$4))) -> 0 | N21: =IF($L21<>1,0,SUMIFS('JLR Materials'!$F$2:$F$20001,'JLR Materials'!$A$2:$A$20001,$K21,'JLR Materials'!$C$2:$C$20001,IF(Settings!$B$2="","<>",Settings!$B$2),'JLR Materials'!$D$2:$D$20001,IF(Settings!$B$4="","<>",Settings!$B$4))) -> 0 | O21: =IF($N21=0,0,IF(Settings!$B$5="percent",$M21*$N21/100,$N21)) -> 0 | P21: =IF($L21<>1,0,SUMIFS('JLR Materials'!$G$2:$G$20001,'JLR Materials'!$A$2:$A$20001,$K21,'JLR Materials'!$C$2:$C$20001,IF(Settings!$B$2="","<>",Settings!$B$2),'JLR Materials'!$D$2:$D$20001,IF(Settings!$B$4="","<>",Settings!$B$4))) -> 0 | Q21: UK CR mild sheet, delivered small-lot. Index-anchored: CRC €781/t → £0.67/kg mill + £0.19/kg stockholder premium. Basis: Fastmarkets EU HRC €691/t May-26 +€90 CRC, FX 0.855. Yield ~140 MPa. | Refresh 2026-09: +£0.049/kg from 1kg crc £0.668→£0.717/kg; premiums held | R21: 2026-09
A22: mat-dc01-gi | B22: DC01 GI (Hot-dip Galvanised) | C22: Galvanised Steel Sheet | D22: =IF($M22>0,$M22,1.11) -> 1.11 | E22: =IF($O22>0,$O22,0.21) -> 0.21 | F22: 7850 | G22: UK | H22: =IF($M22>0,IF($L22<>1,$R22,IFERROR(INDEX('JLR Materials'!$D$2:$D$20001,MATCH($K22,'JLR Materials'!$A$2:$A$20001,0)),$R22)),$R22) -> 2026-09 | I22: =IF($M22>0,"JLR rate card — material code "&$K22,$Q22) -> UK galv coil, BIW bodywork standard. Jun 2026 Index-anchored 2026-07 (see PRICING BASIS). | Refresh 2026-09: +£0.049/kg from 1kg hdg £0.668→£0.717/kg; premiums held | J22: Medium | K22: =IFERROR(INDEX(Mapping!$C$2:$C$549,MATCH($A22,Mapping!$A$2:$A$549,0)),"") | L22: =IF($K22="",0,COUNTIFS('JLR Materials'!$A$2:$A$20001,$K22,'JLR Materials'!$C$2:$C$20001,IF(Settings!$B$2="","<>",Settings!$B$2),'JLR Materials'!$D$2:$D$20001,IF(Settings!$B$4="","<>",Settings!$B$4))) -> 0 | M22: =IF($L22<>1,0,SUMIFS('JLR Materials'!$E$2:$E$20001,'JLR Materials'!$A$2:$A$20001,$K22,'JLR Materials'!$C$2:$C$20001,IF(Settings!$B$2="","<>",Settings!$B$2),'JLR Materials'!$D$2:$D$20001,IF(Settings!$B$4="","<>",Settings!$B$4))) -> 0 | N22: =IF($L22<>1,0,SUMIFS('JLR Materials'!$F$2:$F$20001,'JLR Materials'!$A$2:$A$20001,$K22,'JLR Materials'!$C$2:$C$20001,IF(Settings!$B$2="","<>",Settings!$B$2),'JLR Materials'!$D$2:$D$20001,IF(Settings!$B$4="","<>",Settings!$B$4))) -> 0 | O22: =IF($N22=0,0,IF(Settings!$B$5="percent",$M22*$N22/100,$N22)) -> 0 | P22: =IF($L22<>1,0,SUMIFS('JLR Materials'!$G$2:$G$20001,'JLR Materials'!$A$2:$A$20001,$K22,'JLR Materials'!$C$2:$C$20001,IF(Settings!$B$2="","<>",Settings!$B$2),'JLR Materials'!$D$2:$D$20001,IF(Settings!$B$4="","<>",Settings!$B$4))) -> 0 | Q22: UK galv coil, BIW bodywork standard. Jun 2026 Index-anchored 2026-07 (see PRICING BASIS). | Refresh 2026-09: +£0.049/kg from 1kg hdg £0.668→£0.717/kg; premiums held | R22: 2026-09
